2018-03-13 16:21:29,191 [Thread-3:10352] [django.request:93] [base:get_response] [WARNING]- Not Found: /css/bootstrap.min.css
2018-03-13 16:21:29,295 [Thread-4:11240] [django.request:93] [base:get_response] [WARNING]- Not Found: /js/bootstrap.min.js
2018-03-13 16:21:29,409 [Thread-5:10872] [django.request:93] [base:get_response] [WARNING]- Not Found: /js/bootstrap.min.js
2018-03-13 16:25:19,332 [Thread-7:10456] [django.request:93] [base:get_response] [WARNING]- Not Found: /css/bootstrap.min.css
2018-03-13 16:25:21,662 [Thread-10:5448] [django.request:93] [base:get_response] [WARNING]- Not Found: /css/bootstrap.min.css
2018-03-16 10:35:26,974 [Thread-5:16660] [django.request:93] [base:get_response] [WARNING]- Not Found: /favicon.ico
2018-03-16 11:03:43,793 [Thread-1:22732] [django.request:118] [exception:handle_uncaught_exception] [ERROR]- Internal Server Error: /
Traceback (most recent call last):
  File "C:\Users\Armstromg\Anaconda3\lib\site-packages\django\core\handlers\exception.py", line 35, in inner
    response = get_response(request)
  File "C:\Users\Armstromg\Anaconda3\lib\site-packages\django\core\handlers\base.py", line 128, in _get_response
    response = self.process_exception_by_middleware(e, request)
  File "C:\Users\Armstromg\Anaconda3\lib\site-packages\django\core\handlers\base.py", line 126, in _get_response
    response = wrapped_callback(request, *callback_args, **callback_kwargs)
  File "D:\lilanqing\Project_local\python\maizixueyuan\django-web\bitcs_project\bitcs\views.py", line 9, in index
    stu1.save()
  File "C:\Users\Armstromg\Anaconda3\lib\site-packages\mongoengine\document.py", line 367, in save
    self.ensure_indexes()
  File "C:\Users\Armstromg\Anaconda3\lib\site-packages\mongoengine\document.py", line 849, in ensure_indexes
    collection = cls._get_collection()
  File "C:\Users\Armstromg\Anaconda3\lib\site-packages\mongoengine\document.py", line 190, in _get_collection
    db = cls._get_db()
  File "C:\Users\Armstromg\Anaconda3\lib\site-packages\mongoengine\document.py", line 179, in _get_db
    return get_db(cls._meta.get('db_alias', DEFAULT_CONNECTION_NAME))
  File "C:\Users\Armstromg\Anaconda3\lib\site-packages\mongoengine\connection.py", line 235, in get_db
    db.authenticate(conn_settings['username'], conn_settings['password'], **auth_kwargs)
  File "C:\Users\Armstromg\Anaconda3\lib\site-packages\pymongo\database.py", line 1048, in authenticate
    connect=True)
  File "C:\Users\Armstromg\Anaconda3\lib\site-packages\pymongo\mongo_client.py", line 500, in _cache_credentials
    writable_preferred_server_selector)
  File "C:\Users\Armstromg\Anaconda3\lib\site-packages\pymongo\topology.py", line 214, in select_server
    address))
  File "C:\Users\Armstromg\Anaconda3\lib\site-packages\pymongo\topology.py", line 189, in select_servers
    self._error_message(selector))
pymongo.errors.ServerSelectionTimeoutError: 124.193.169.159:27017: [WinError 10061] 由于目标计算机积极拒绝，无法连接。
2018-03-16 11:04:24,736 [Thread-5:23816] [django.request:118] [exception:handle_uncaught_exception] [ERROR]- Internal Server Error: /
Traceback (most recent call last):
  File "C:\Users\Armstromg\Anaconda3\lib\site-packages\django\core\handlers\exception.py", line 35, in inner
    response = get_response(request)
  File "C:\Users\Armstromg\Anaconda3\lib\site-packages\django\core\handlers\base.py", line 128, in _get_response
    response = self.process_exception_by_middleware(e, request)
  File "C:\Users\Armstromg\Anaconda3\lib\site-packages\django\core\handlers\base.py", line 126, in _get_response
    response = wrapped_callback(request, *callback_args, **callback_kwargs)
  File "D:\lilanqing\Project_local\python\maizixueyuan\django-web\bitcs_project\bitcs\views.py", line 9, in index
    stu1.save()
  File "C:\Users\Armstromg\Anaconda3\lib\site-packages\mongoengine\document.py", line 367, in save
    self.ensure_indexes()
  File "C:\Users\Armstromg\Anaconda3\lib\site-packages\mongoengine\document.py", line 849, in ensure_indexes
    collection = cls._get_collection()
  File "C:\Users\Armstromg\Anaconda3\lib\site-packages\mongoengine\document.py", line 190, in _get_collection
    db = cls._get_db()
  File "C:\Users\Armstromg\Anaconda3\lib\site-packages\mongoengine\document.py", line 179, in _get_db
    return get_db(cls._meta.get('db_alias', DEFAULT_CONNECTION_NAME))
  File "C:\Users\Armstromg\Anaconda3\lib\site-packages\mongoengine\connection.py", line 235, in get_db
    db.authenticate(conn_settings['username'], conn_settings['password'], **auth_kwargs)
  File "C:\Users\Armstromg\Anaconda3\lib\site-packages\pymongo\database.py", line 1048, in authenticate
    connect=True)
  File "C:\Users\Armstromg\Anaconda3\lib\site-packages\pymongo\mongo_client.py", line 500, in _cache_credentials
    writable_preferred_server_selector)
  File "C:\Users\Armstromg\Anaconda3\lib\site-packages\pymongo\topology.py", line 214, in select_server
    address))
  File "C:\Users\Armstromg\Anaconda3\lib\site-packages\pymongo\topology.py", line 189, in select_servers
    self._error_message(selector))
pymongo.errors.ServerSelectionTimeoutError: 124.193.169.159:27017: [WinError 10061] 由于目标计算机积极拒绝，无法连接。
2018-03-16 11:06:03,979 [Thread-1:24876] [django.request:118] [exception:handle_uncaught_exception] [ERROR]- Internal Server Error: /
Traceback (most recent call last):
  File "C:\Users\Armstromg\Anaconda3\lib\site-packages\django\core\handlers\exception.py", line 35, in inner
    response = get_response(request)
  File "C:\Users\Armstromg\Anaconda3\lib\site-packages\django\core\handlers\base.py", line 128, in _get_response
    response = self.process_exception_by_middleware(e, request)
  File "C:\Users\Armstromg\Anaconda3\lib\site-packages\django\core\handlers\base.py", line 126, in _get_response
    response = wrapped_callback(request, *callback_args, **callback_kwargs)
  File "D:\lilanqing\Project_local\python\maizixueyuan\django-web\bitcs_project\bitcs\views.py", line 9, in index
    stu1.save()
  File "C:\Users\Armstromg\Anaconda3\lib\site-packages\mongoengine\document.py", line 367, in save
    self.ensure_indexes()
  File "C:\Users\Armstromg\Anaconda3\lib\site-packages\mongoengine\document.py", line 849, in ensure_indexes
    collection = cls._get_collection()
  File "C:\Users\Armstromg\Anaconda3\lib\site-packages\mongoengine\document.py", line 190, in _get_collection
    db = cls._get_db()
  File "C:\Users\Armstromg\Anaconda3\lib\site-packages\mongoengine\document.py", line 179, in _get_db
    return get_db(cls._meta.get('db_alias', DEFAULT_CONNECTION_NAME))
  File "C:\Users\Armstromg\Anaconda3\lib\site-packages\mongoengine\connection.py", line 235, in get_db
    db.authenticate(conn_settings['username'], conn_settings['password'], **auth_kwargs)
  File "C:\Users\Armstromg\Anaconda3\lib\site-packages\pymongo\database.py", line 1048, in authenticate
    connect=True)
  File "C:\Users\Armstromg\Anaconda3\lib\site-packages\pymongo\mongo_client.py", line 505, in _cache_credentials
    sock_info.authenticate(credentials)
  File "C:\Users\Armstromg\Anaconda3\lib\site-packages\pymongo\pool.py", line 523, in authenticate
    auth.authenticate(credentials, self)
  File "C:\Users\Armstromg\Anaconda3\lib\site-packages\pymongo\auth.py", line 470, in authenticate
    auth_func(credentials, sock_info)
  File "C:\Users\Armstromg\Anaconda3\lib\site-packages\pymongo\auth.py", line 450, in _authenticate_default
    return _authenticate_scram_sha1(credentials, sock_info)
  File "C:\Users\Armstromg\Anaconda3\lib\site-packages\pymongo\auth.py", line 201, in _authenticate_scram_sha1
    res = sock_info.command(source, cmd)
  File "C:\Users\Armstromg\Anaconda3\lib\site-packages\pymongo\pool.py", line 419, in command
    collation=collation)
  File "C:\Users\Armstromg\Anaconda3\lib\site-packages\pymongo\network.py", line 116, in command
    parse_write_concern_error=parse_write_concern_error)
  File "C:\Users\Armstromg\Anaconda3\lib\site-packages\pymongo\helpers.py", line 210, in _check_command_response
    raise OperationFailure(msg % errmsg, code, response)
pymongo.errors.OperationFailure: Authentication failed.
2018-03-16 11:06:39,854 [Thread-3:25556] [django.request:118] [exception:handle_uncaught_exception] [ERROR]- Internal Server Error: /
Traceback (most recent call last):
  File "C:\Users\Armstromg\Anaconda3\lib\site-packages\django\core\handlers\exception.py", line 35, in inner
    response = get_response(request)
  File "C:\Users\Armstromg\Anaconda3\lib\site-packages\django\core\handlers\base.py", line 128, in _get_response
    response = self.process_exception_by_middleware(e, request)
  File "C:\Users\Armstromg\Anaconda3\lib\site-packages\django\core\handlers\base.py", line 126, in _get_response
    response = wrapped_callback(request, *callback_args, **callback_kwargs)
  File "D:\lilanqing\Project_local\python\maizixueyuan\django-web\bitcs_project\bitcs\views.py", line 9, in index
    stu1.save()
  File "C:\Users\Armstromg\Anaconda3\lib\site-packages\mongoengine\document.py", line 367, in save
    self.ensure_indexes()
  File "C:\Users\Armstromg\Anaconda3\lib\site-packages\mongoengine\document.py", line 849, in ensure_indexes
    collection = cls._get_collection()
  File "C:\Users\Armstromg\Anaconda3\lib\site-packages\mongoengine\document.py", line 190, in _get_collection
    db = cls._get_db()
  File "C:\Users\Armstromg\Anaconda3\lib\site-packages\mongoengine\document.py", line 179, in _get_db
    return get_db(cls._meta.get('db_alias', DEFAULT_CONNECTION_NAME))
  File "C:\Users\Armstromg\Anaconda3\lib\site-packages\mongoengine\connection.py", line 235, in get_db
    db.authenticate(conn_settings['username'], conn_settings['password'], **auth_kwargs)
  File "C:\Users\Armstromg\Anaconda3\lib\site-packages\pymongo\database.py", line 1048, in authenticate
    connect=True)
  File "C:\Users\Armstromg\Anaconda3\lib\site-packages\pymongo\mongo_client.py", line 505, in _cache_credentials
    sock_info.authenticate(credentials)
  File "C:\Users\Armstromg\Anaconda3\lib\site-packages\pymongo\pool.py", line 523, in authenticate
    auth.authenticate(credentials, self)
  File "C:\Users\Armstromg\Anaconda3\lib\site-packages\pymongo\auth.py", line 470, in authenticate
    auth_func(credentials, sock_info)
  File "C:\Users\Armstromg\Anaconda3\lib\site-packages\pymongo\auth.py", line 450, in _authenticate_default
    return _authenticate_scram_sha1(credentials, sock_info)
  File "C:\Users\Armstromg\Anaconda3\lib\site-packages\pymongo\auth.py", line 201, in _authenticate_scram_sha1
    res = sock_info.command(source, cmd)
  File "C:\Users\Armstromg\Anaconda3\lib\site-packages\pymongo\pool.py", line 419, in command
    collation=collation)
  File "C:\Users\Armstromg\Anaconda3\lib\site-packages\pymongo\network.py", line 116, in command
    parse_write_concern_error=parse_write_concern_error)
  File "C:\Users\Armstromg\Anaconda3\lib\site-packages\pymongo\helpers.py", line 210, in _check_command_response
    raise OperationFailure(msg % errmsg, code, response)
pymongo.errors.OperationFailure: Authentication failed.
2018-03-16 11:06:51,972 [Thread-1:24976] [django.request:118] [exception:handle_uncaught_exception] [ERROR]- Internal Server Error: /
Traceback (most recent call last):
  File "C:\Users\Armstromg\Anaconda3\lib\site-packages\django\core\handlers\exception.py", line 35, in inner
    response = get_response(request)
  File "C:\Users\Armstromg\Anaconda3\lib\site-packages\django\core\handlers\base.py", line 128, in _get_response
    response = self.process_exception_by_middleware(e, request)
  File "C:\Users\Armstromg\Anaconda3\lib\site-packages\django\core\handlers\base.py", line 126, in _get_response
    response = wrapped_callback(request, *callback_args, **callback_kwargs)
  File "D:\lilanqing\Project_local\python\maizixueyuan\django-web\bitcs_project\bitcs\views.py", line 9, in index
    stu1.save()
  File "C:\Users\Armstromg\Anaconda3\lib\site-packages\mongoengine\document.py", line 367, in save
    self.ensure_indexes()
  File "C:\Users\Armstromg\Anaconda3\lib\site-packages\mongoengine\document.py", line 849, in ensure_indexes
    collection = cls._get_collection()
  File "C:\Users\Armstromg\Anaconda3\lib\site-packages\mongoengine\document.py", line 190, in _get_collection
    db = cls._get_db()
  File "C:\Users\Armstromg\Anaconda3\lib\site-packages\mongoengine\document.py", line 179, in _get_db
    return get_db(cls._meta.get('db_alias', DEFAULT_CONNECTION_NAME))
  File "C:\Users\Armstromg\Anaconda3\lib\site-packages\mongoengine\connection.py", line 235, in get_db
    db.authenticate(conn_settings['username'], conn_settings['password'], **auth_kwargs)
  File "C:\Users\Armstromg\Anaconda3\lib\site-packages\pymongo\database.py", line 1048, in authenticate
    connect=True)
  File "C:\Users\Armstromg\Anaconda3\lib\site-packages\pymongo\mongo_client.py", line 505, in _cache_credentials
    sock_info.authenticate(credentials)
  File "C:\Users\Armstromg\Anaconda3\lib\site-packages\pymongo\pool.py", line 523, in authenticate
    auth.authenticate(credentials, self)
  File "C:\Users\Armstromg\Anaconda3\lib\site-packages\pymongo\auth.py", line 470, in authenticate
    auth_func(credentials, sock_info)
  File "C:\Users\Armstromg\Anaconda3\lib\site-packages\pymongo\auth.py", line 450, in _authenticate_default
    return _authenticate_scram_sha1(credentials, sock_info)
  File "C:\Users\Armstromg\Anaconda3\lib\site-packages\pymongo\auth.py", line 201, in _authenticate_scram_sha1
    res = sock_info.command(source, cmd)
  File "C:\Users\Armstromg\Anaconda3\lib\site-packages\pymongo\pool.py", line 419, in command
    collation=collation)
  File "C:\Users\Armstromg\Anaconda3\lib\site-packages\pymongo\network.py", line 116, in command
    parse_write_concern_error=parse_write_concern_error)
  File "C:\Users\Armstromg\Anaconda3\lib\site-packages\pymongo\helpers.py", line 210, in _check_command_response
    raise OperationFailure(msg % errmsg, code, response)
pymongo.errors.OperationFailure: Authentication failed.
2018-03-16 11:11:00,101 [Thread-3:26172] [django.request:118] [exception:handle_uncaught_exception] [ERROR]- Internal Server Error: /
Traceback (most recent call last):
  File "C:\Users\Armstromg\Anaconda3\lib\site-packages\django\core\handlers\exception.py", line 35, in inner
    response = get_response(request)
  File "C:\Users\Armstromg\Anaconda3\lib\site-packages\django\core\handlers\base.py", line 128, in _get_response
    response = self.process_exception_by_middleware(e, request)
  File "C:\Users\Armstromg\Anaconda3\lib\site-packages\django\core\handlers\base.py", line 126, in _get_response
    response = wrapped_callback(request, *callback_args, **callback_kwargs)
  File "D:\lilanqing\Project_local\python\maizixueyuan\django-web\bitcs_project\bitcs\views.py", line 9, in index
    stu1.save()
  File "C:\Users\Armstromg\Anaconda3\lib\site-packages\mongoengine\document.py", line 367, in save
    self.ensure_indexes()
  File "C:\Users\Armstromg\Anaconda3\lib\site-packages\mongoengine\document.py", line 849, in ensure_indexes
    collection = cls._get_collection()
  File "C:\Users\Armstromg\Anaconda3\lib\site-packages\mongoengine\document.py", line 190, in _get_collection
    db = cls._get_db()
  File "C:\Users\Armstromg\Anaconda3\lib\site-packages\mongoengine\document.py", line 179, in _get_db
    return get_db(cls._meta.get('db_alias', DEFAULT_CONNECTION_NAME))
  File "C:\Users\Armstromg\Anaconda3\lib\site-packages\mongoengine\connection.py", line 235, in get_db
    db.authenticate(conn_settings['username'], conn_settings['password'], **auth_kwargs)
  File "C:\Users\Armstromg\Anaconda3\lib\site-packages\pymongo\database.py", line 1048, in authenticate
    connect=True)
  File "C:\Users\Armstromg\Anaconda3\lib\site-packages\pymongo\mongo_client.py", line 505, in _cache_credentials
    sock_info.authenticate(credentials)
  File "C:\Users\Armstromg\Anaconda3\lib\site-packages\pymongo\pool.py", line 523, in authenticate
    auth.authenticate(credentials, self)
  File "C:\Users\Armstromg\Anaconda3\lib\site-packages\pymongo\auth.py", line 470, in authenticate
    auth_func(credentials, sock_info)
  File "C:\Users\Armstromg\Anaconda3\lib\site-packages\pymongo\auth.py", line 450, in _authenticate_default
    return _authenticate_scram_sha1(credentials, sock_info)
  File "C:\Users\Armstromg\Anaconda3\lib\site-packages\pymongo\auth.py", line 201, in _authenticate_scram_sha1
    res = sock_info.command(source, cmd)
  File "C:\Users\Armstromg\Anaconda3\lib\site-packages\pymongo\pool.py", line 419, in command
    collation=collation)
  File "C:\Users\Armstromg\Anaconda3\lib\site-packages\pymongo\network.py", line 116, in command
    parse_write_concern_error=parse_write_concern_error)
  File "C:\Users\Armstromg\Anaconda3\lib\site-packages\pymongo\helpers.py", line 210, in _check_command_response
    raise OperationFailure(msg % errmsg, code, response)
pymongo.errors.OperationFailure: Authentication failed.
2018-03-16 11:11:37,295 [Thread-1:25988] [django.request:118] [exception:handle_uncaught_exception] [ERROR]- Internal Server Error: /
Traceback (most recent call last):
  File "C:\Users\Armstromg\Anaconda3\lib\site-packages\django\core\handlers\exception.py", line 35, in inner
    response = get_response(request)
  File "C:\Users\Armstromg\Anaconda3\lib\site-packages\django\core\handlers\base.py", line 128, in _get_response
    response = self.process_exception_by_middleware(e, request)
  File "C:\Users\Armstromg\Anaconda3\lib\site-packages\django\core\handlers\base.py", line 126, in _get_response
    response = wrapped_callback(request, *callback_args, **callback_kwargs)
  File "D:\lilanqing\Project_local\python\maizixueyuan\django-web\bitcs_project\bitcs\views.py", line 9, in index
    stu1.save()
  File "C:\Users\Armstromg\Anaconda3\lib\site-packages\mongoengine\document.py", line 367, in save
    self.ensure_indexes()
  File "C:\Users\Armstromg\Anaconda3\lib\site-packages\mongoengine\document.py", line 849, in ensure_indexes
    collection = cls._get_collection()
  File "C:\Users\Armstromg\Anaconda3\lib\site-packages\mongoengine\document.py", line 190, in _get_collection
    db = cls._get_db()
  File "C:\Users\Armstromg\Anaconda3\lib\site-packages\mongoengine\document.py", line 179, in _get_db
    return get_db(cls._meta.get('db_alias', DEFAULT_CONNECTION_NAME))
  File "C:\Users\Armstromg\Anaconda3\lib\site-packages\mongoengine\connection.py", line 235, in get_db
    db.authenticate(conn_settings['username'], conn_settings['password'], **auth_kwargs)
  File "C:\Users\Armstromg\Anaconda3\lib\site-packages\pymongo\database.py", line 1048, in authenticate
    connect=True)
  File "C:\Users\Armstromg\Anaconda3\lib\site-packages\pymongo\mongo_client.py", line 505, in _cache_credentials
    sock_info.authenticate(credentials)
  File "C:\Users\Armstromg\Anaconda3\lib\site-packages\pymongo\pool.py", line 523, in authenticate
    auth.authenticate(credentials, self)
  File "C:\Users\Armstromg\Anaconda3\lib\site-packages\pymongo\auth.py", line 470, in authenticate
    auth_func(credentials, sock_info)
  File "C:\Users\Armstromg\Anaconda3\lib\site-packages\pymongo\auth.py", line 450, in _authenticate_default
    return _authenticate_scram_sha1(credentials, sock_info)
  File "C:\Users\Armstromg\Anaconda3\lib\site-packages\pymongo\auth.py", line 201, in _authenticate_scram_sha1
    res = sock_info.command(source, cmd)
  File "C:\Users\Armstromg\Anaconda3\lib\site-packages\pymongo\pool.py", line 419, in command
    collation=collation)
  File "C:\Users\Armstromg\Anaconda3\lib\site-packages\pymongo\network.py", line 116, in command
    parse_write_concern_error=parse_write_concern_error)
  File "C:\Users\Armstromg\Anaconda3\lib\site-packages\pymongo\helpers.py", line 210, in _check_command_response
    raise OperationFailure(msg % errmsg, code, response)
pymongo.errors.OperationFailure: Authentication failed.
2018-03-16 11:11:39,468 [Thread-3:22612] [django.request:118] [exception:handle_uncaught_exception] [ERROR]- Internal Server Error: /
Traceback (most recent call last):
  File "C:\Users\Armstromg\Anaconda3\lib\site-packages\django\core\handlers\exception.py", line 35, in inner
    response = get_response(request)
  File "C:\Users\Armstromg\Anaconda3\lib\site-packages\django\core\handlers\base.py", line 128, in _get_response
    response = self.process_exception_by_middleware(e, request)
  File "C:\Users\Armstromg\Anaconda3\lib\site-packages\django\core\handlers\base.py", line 126, in _get_response
    response = wrapped_callback(request, *callback_args, **callback_kwargs)
  File "D:\lilanqing\Project_local\python\maizixueyuan\django-web\bitcs_project\bitcs\views.py", line 9, in index
    stu1.save()
  File "C:\Users\Armstromg\Anaconda3\lib\site-packages\mongoengine\document.py", line 367, in save
    self.ensure_indexes()
  File "C:\Users\Armstromg\Anaconda3\lib\site-packages\mongoengine\document.py", line 849, in ensure_indexes
    collection = cls._get_collection()
  File "C:\Users\Armstromg\Anaconda3\lib\site-packages\mongoengine\document.py", line 190, in _get_collection
    db = cls._get_db()
  File "C:\Users\Armstromg\Anaconda3\lib\site-packages\mongoengine\document.py", line 179, in _get_db
    return get_db(cls._meta.get('db_alias', DEFAULT_CONNECTION_NAME))
  File "C:\Users\Armstromg\Anaconda3\lib\site-packages\mongoengine\connection.py", line 235, in get_db
    db.authenticate(conn_settings['username'], conn_settings['password'], **auth_kwargs)
  File "C:\Users\Armstromg\Anaconda3\lib\site-packages\pymongo\database.py", line 1048, in authenticate
    connect=True)
  File "C:\Users\Armstromg\Anaconda3\lib\site-packages\pymongo\mongo_client.py", line 505, in _cache_credentials
    sock_info.authenticate(credentials)
  File "C:\Users\Armstromg\Anaconda3\lib\site-packages\pymongo\pool.py", line 523, in authenticate
    auth.authenticate(credentials, self)
  File "C:\Users\Armstromg\Anaconda3\lib\site-packages\pymongo\auth.py", line 470, in authenticate
    auth_func(credentials, sock_info)
  File "C:\Users\Armstromg\Anaconda3\lib\site-packages\pymongo\auth.py", line 450, in _authenticate_default
    return _authenticate_scram_sha1(credentials, sock_info)
  File "C:\Users\Armstromg\Anaconda3\lib\site-packages\pymongo\auth.py", line 201, in _authenticate_scram_sha1
    res = sock_info.command(source, cmd)
  File "C:\Users\Armstromg\Anaconda3\lib\site-packages\pymongo\pool.py", line 419, in command
    collation=collation)
  File "C:\Users\Armstromg\Anaconda3\lib\site-packages\pymongo\network.py", line 116, in command
    parse_write_concern_error=parse_write_concern_error)
  File "C:\Users\Armstromg\Anaconda3\lib\site-packages\pymongo\helpers.py", line 210, in _check_command_response
    raise OperationFailure(msg % errmsg, code, response)
pymongo.errors.OperationFailure: Authentication failed.
2018-03-16 11:11:57,370 [Thread-1:26548] [django.request:118] [exception:handle_uncaught_exception] [ERROR]- Internal Server Error: /
Traceback (most recent call last):
  File "C:\Users\Armstromg\Anaconda3\lib\site-packages\django\core\handlers\exception.py", line 35, in inner
    response = get_response(request)
  File "C:\Users\Armstromg\Anaconda3\lib\site-packages\django\core\handlers\base.py", line 128, in _get_response
    response = self.process_exception_by_middleware(e, request)
  File "C:\Users\Armstromg\Anaconda3\lib\site-packages\django\core\handlers\base.py", line 126, in _get_response
    response = wrapped_callback(request, *callback_args, **callback_kwargs)
  File "D:\lilanqing\Project_local\python\maizixueyuan\django-web\bitcs_project\bitcs\views.py", line 9, in index
    stu1.save()
  File "C:\Users\Armstromg\Anaconda3\lib\site-packages\mongoengine\document.py", line 367, in save
    self.ensure_indexes()
  File "C:\Users\Armstromg\Anaconda3\lib\site-packages\mongoengine\document.py", line 849, in ensure_indexes
    collection = cls._get_collection()
  File "C:\Users\Armstromg\Anaconda3\lib\site-packages\mongoengine\document.py", line 190, in _get_collection
    db = cls._get_db()
  File "C:\Users\Armstromg\Anaconda3\lib\site-packages\mongoengine\document.py", line 179, in _get_db
    return get_db(cls._meta.get('db_alias', DEFAULT_CONNECTION_NAME))
  File "C:\Users\Armstromg\Anaconda3\lib\site-packages\mongoengine\connection.py", line 235, in get_db
    db.authenticate(conn_settings['username'], conn_settings['password'], **auth_kwargs)
  File "C:\Users\Armstromg\Anaconda3\lib\site-packages\pymongo\database.py", line 1048, in authenticate
    connect=True)
  File "C:\Users\Armstromg\Anaconda3\lib\site-packages\pymongo\mongo_client.py", line 505, in _cache_credentials
    sock_info.authenticate(credentials)
  File "C:\Users\Armstromg\Anaconda3\lib\site-packages\pymongo\pool.py", line 523, in authenticate
    auth.authenticate(credentials, self)
  File "C:\Users\Armstromg\Anaconda3\lib\site-packages\pymongo\auth.py", line 470, in authenticate
    auth_func(credentials, sock_info)
  File "C:\Users\Armstromg\Anaconda3\lib\site-packages\pymongo\auth.py", line 450, in _authenticate_default
    return _authenticate_scram_sha1(credentials, sock_info)
  File "C:\Users\Armstromg\Anaconda3\lib\site-packages\pymongo\auth.py", line 201, in _authenticate_scram_sha1
    res = sock_info.command(source, cmd)
  File "C:\Users\Armstromg\Anaconda3\lib\site-packages\pymongo\pool.py", line 419, in command
    collation=collation)
  File "C:\Users\Armstromg\Anaconda3\lib\site-packages\pymongo\network.py", line 116, in command
    parse_write_concern_error=parse_write_concern_error)
  File "C:\Users\Armstromg\Anaconda3\lib\site-packages\pymongo\helpers.py", line 210, in _check_command_response
    raise OperationFailure(msg % errmsg, code, response)
pymongo.errors.OperationFailure: Authentication failed.
2018-03-16 11:15:24,753 [Thread-1:27612] [django.request:118] [exception:handle_uncaught_exception] [ERROR]- Internal Server Error: /
Traceback (most recent call last):
  File "C:\Users\Armstromg\Anaconda3\lib\site-packages\django\core\handlers\exception.py", line 35, in inner
    response = get_response(request)
  File "C:\Users\Armstromg\Anaconda3\lib\site-packages\django\core\handlers\base.py", line 128, in _get_response
    response = self.process_exception_by_middleware(e, request)
  File "C:\Users\Armstromg\Anaconda3\lib\site-packages\django\core\handlers\base.py", line 126, in _get_response
    response = wrapped_callback(request, *callback_args, **callback_kwargs)
  File "D:\lilanqing\Project_local\python\maizixueyuan\django-web\bitcs_project\bitcs\views.py", line 9, in index
    stu1.save()
  File "C:\Users\Armstromg\Anaconda3\lib\site-packages\mongoengine\document.py", line 367, in save
    self.ensure_indexes()
  File "C:\Users\Armstromg\Anaconda3\lib\site-packages\mongoengine\document.py", line 849, in ensure_indexes
    collection = cls._get_collection()
  File "C:\Users\Armstromg\Anaconda3\lib\site-packages\mongoengine\document.py", line 190, in _get_collection
    db = cls._get_db()
  File "C:\Users\Armstromg\Anaconda3\lib\site-packages\mongoengine\document.py", line 179, in _get_db
    return get_db(cls._meta.get('db_alias', DEFAULT_CONNECTION_NAME))
  File "C:\Users\Armstromg\Anaconda3\lib\site-packages\mongoengine\connection.py", line 235, in get_db
    db.authenticate(conn_settings['username'], conn_settings['password'], **auth_kwargs)
  File "C:\Users\Armstromg\Anaconda3\lib\site-packages\pymongo\database.py", line 1048, in authenticate
    connect=True)
  File "C:\Users\Armstromg\Anaconda3\lib\site-packages\pymongo\mongo_client.py", line 505, in _cache_credentials
    sock_info.authenticate(credentials)
  File "C:\Users\Armstromg\Anaconda3\lib\site-packages\pymongo\pool.py", line 523, in authenticate
    auth.authenticate(credentials, self)
  File "C:\Users\Armstromg\Anaconda3\lib\site-packages\pymongo\auth.py", line 470, in authenticate
    auth_func(credentials, sock_info)
  File "C:\Users\Armstromg\Anaconda3\lib\site-packages\pymongo\auth.py", line 450, in _authenticate_default
    return _authenticate_scram_sha1(credentials, sock_info)
  File "C:\Users\Armstromg\Anaconda3\lib\site-packages\pymongo\auth.py", line 201, in _authenticate_scram_sha1
    res = sock_info.command(source, cmd)
  File "C:\Users\Armstromg\Anaconda3\lib\site-packages\pymongo\pool.py", line 419, in command
    collation=collation)
  File "C:\Users\Armstromg\Anaconda3\lib\site-packages\pymongo\network.py", line 116, in command
    parse_write_concern_error=parse_write_concern_error)
  File "C:\Users\Armstromg\Anaconda3\lib\site-packages\pymongo\helpers.py", line 210, in _check_command_response
    raise OperationFailure(msg % errmsg, code, response)
pymongo.errors.OperationFailure: Authentication failed.
2018-03-16 11:23:28,048 [Thread-1:29664] [django.request:118] [exception:handle_uncaught_exception] [ERROR]- Internal Server Error: /
Traceback (most recent call last):
  File "C:\Users\Armstromg\Anaconda3\lib\site-packages\django\core\handlers\exception.py", line 35, in inner
    response = get_response(request)
  File "C:\Users\Armstromg\Anaconda3\lib\site-packages\django\core\handlers\base.py", line 128, in _get_response
    response = self.process_exception_by_middleware(e, request)
  File "C:\Users\Armstromg\Anaconda3\lib\site-packages\django\core\handlers\base.py", line 126, in _get_response
    response = wrapped_callback(request, *callback_args, **callback_kwargs)
  File "D:\lilanqing\Project_local\python\maizixueyuan\django-web\bitcs_project\bitcs\views.py", line 8, in index
    inf_list = Inforday.objects.all()[1]
  File "C:\Users\Armstromg\Anaconda3\lib\site-packages\mongoengine\queryset\base.py", line 199, in __getitem__
    only_fields=self.only_fields
  File "C:\Users\Armstromg\Anaconda3\lib\site-packages\mongoengine\base\document.py", line 721, in _from_son
    obj = cls(__auto_convert=False, _created=created, __only_fields=only_fields, **data)
  File "C:\Users\Armstromg\Anaconda3\lib\site-packages\mongoengine\base\document.py", line 77, in __init__
    raise FieldDoesNotExist(msg)
mongoengine.errors.FieldDoesNotExist: The fields "{'ExhTime', 'Category', 'fromTime', 'time', 'srcUrl', 'Name', 'url', 'content'}" do not exist on the document "Inforday"
2018-03-16 11:28:49,185 [Thread-1:29788] [django.request:118] [exception:handle_uncaught_exception] [ERROR]- Internal Server Error: /
Traceback (most recent call last):
  File "C:\Users\Armstromg\Anaconda3\lib\site-packages\django\core\handlers\exception.py", line 35, in inner
    response = get_response(request)
  File "C:\Users\Armstromg\Anaconda3\lib\site-packages\django\core\handlers\base.py", line 128, in _get_response
    response = self.process_exception_by_middleware(e, request)
  File "C:\Users\Armstromg\Anaconda3\lib\site-packages\django\core\handlers\base.py", line 126, in _get_response
    response = wrapped_callback(request, *callback_args, **callback_kwargs)
  File "D:\lilanqing\Project_local\python\maizixueyuan\django-web\bitcs_project\bitcs\views.py", line 9, in index
    print(inf_list.name)
AttributeError: 'Inforday' object has no attribute 'name'
2018-03-16 14:36:05,042 [Thread-54:74908] [django.request:93] [base:get_response] [WARNING]- Not Found: /mainPage.php
2018-03-16 14:39:55,214 [Thread-69:76484] [django.request:93] [base:get_response] [WARNING]- Not Found: /favicon.ico
2018-03-16 14:45:42,837 [Thread-1:77076] [django.request:118] [exception:handle_uncaught_exception] [ERROR]- Internal Server Error: /
Traceback (most recent call last):
  File "C:\Users\Armstromg\Anaconda3\lib\site-packages\django\core\handlers\exception.py", line 35, in inner
    response = get_response(request)
  File "C:\Users\Armstromg\Anaconda3\lib\site-packages\django\core\handlers\base.py", line 128, in _get_response
    response = self.process_exception_by_middleware(e, request)
  File "C:\Users\Armstromg\Anaconda3\lib\site-packages\django\core\handlers\base.py", line 126, in _get_response
    response = wrapped_callback(request, *callback_args, **callback_kwargs)
  File "D:\lilanqing\Project_local\python\maizixueyuan\django-web\bitcs_project\bitcs\views.py", line 9, in index
    inf_list = Inforday.objects.all()
  File "C:\Users\Armstromg\Anaconda3\lib\site-packages\mongoengine\queryset\manager.py", line 37, in __get__
    queryset = queryset_class(owner, owner._get_collection())
  File "C:\Users\Armstromg\Anaconda3\lib\site-packages\mongoengine\document.py", line 190, in _get_collection
    db = cls._get_db()
  File "C:\Users\Armstromg\Anaconda3\lib\site-packages\mongoengine\document.py", line 179, in _get_db
    return get_db(cls._meta.get('db_alias', DEFAULT_CONNECTION_NAME))
  File "C:\Users\Armstromg\Anaconda3\lib\site-packages\mongoengine\connection.py", line 235, in get_db
    db.authenticate(conn_settings['username'], conn_settings['password'], **auth_kwargs)
  File "C:\Users\Armstromg\Anaconda3\lib\site-packages\pymongo\database.py", line 1048, in authenticate
    connect=True)
  File "C:\Users\Armstromg\Anaconda3\lib\site-packages\pymongo\mongo_client.py", line 505, in _cache_credentials
    sock_info.authenticate(credentials)
  File "C:\Users\Armstromg\Anaconda3\lib\site-packages\pymongo\pool.py", line 523, in authenticate
    auth.authenticate(credentials, self)
  File "C:\Users\Armstromg\Anaconda3\lib\site-packages\pymongo\auth.py", line 470, in authenticate
    auth_func(credentials, sock_info)
  File "C:\Users\Armstromg\Anaconda3\lib\site-packages\pymongo\auth.py", line 450, in _authenticate_default
    return _authenticate_scram_sha1(credentials, sock_info)
  File "C:\Users\Armstromg\Anaconda3\lib\site-packages\pymongo\auth.py", line 201, in _authenticate_scram_sha1
    res = sock_info.command(source, cmd)
  File "C:\Users\Armstromg\Anaconda3\lib\site-packages\pymongo\pool.py", line 419, in command
    collation=collation)
  File "C:\Users\Armstromg\Anaconda3\lib\site-packages\pymongo\network.py", line 116, in command
    parse_write_concern_error=parse_write_concern_error)
  File "C:\Users\Armstromg\Anaconda3\lib\site-packages\pymongo\helpers.py", line 210, in _check_command_response
    raise OperationFailure(msg % errmsg, code, response)
pymongo.errors.OperationFailure: Authentication failed.
2018-03-16 14:45:54,814 [Thread-4:32864] [django.request:118] [exception:handle_uncaught_exception] [ERROR]- Internal Server Error: /
Traceback (most recent call last):
  File "C:\Users\Armstromg\Anaconda3\lib\site-packages\django\core\handlers\exception.py", line 35, in inner
    response = get_response(request)
  File "C:\Users\Armstromg\Anaconda3\lib\site-packages\django\core\handlers\base.py", line 128, in _get_response
    response = self.process_exception_by_middleware(e, request)
  File "C:\Users\Armstromg\Anaconda3\lib\site-packages\django\core\handlers\base.py", line 126, in _get_response
    response = wrapped_callback(request, *callback_args, **callback_kwargs)
  File "D:\lilanqing\Project_local\python\maizixueyuan\django-web\bitcs_project\bitcs\views.py", line 9, in index
    inf_list = Inforday.objects.all()
  File "C:\Users\Armstromg\Anaconda3\lib\site-packages\mongoengine\queryset\manager.py", line 37, in __get__
    queryset = queryset_class(owner, owner._get_collection())
  File "C:\Users\Armstromg\Anaconda3\lib\site-packages\mongoengine\document.py", line 190, in _get_collection
    db = cls._get_db()
  File "C:\Users\Armstromg\Anaconda3\lib\site-packages\mongoengine\document.py", line 179, in _get_db
    return get_db(cls._meta.get('db_alias', DEFAULT_CONNECTION_NAME))
  File "C:\Users\Armstromg\Anaconda3\lib\site-packages\mongoengine\connection.py", line 235, in get_db
    db.authenticate(conn_settings['username'], conn_settings['password'], **auth_kwargs)
  File "C:\Users\Armstromg\Anaconda3\lib\site-packages\pymongo\database.py", line 1048, in authenticate
    connect=True)
  File "C:\Users\Armstromg\Anaconda3\lib\site-packages\pymongo\mongo_client.py", line 505, in _cache_credentials
    sock_info.authenticate(credentials)
  File "C:\Users\Armstromg\Anaconda3\lib\site-packages\pymongo\pool.py", line 523, in authenticate
    auth.authenticate(credentials, self)
  File "C:\Users\Armstromg\Anaconda3\lib\site-packages\pymongo\auth.py", line 470, in authenticate
    auth_func(credentials, sock_info)
  File "C:\Users\Armstromg\Anaconda3\lib\site-packages\pymongo\auth.py", line 450, in _authenticate_default
    return _authenticate_scram_sha1(credentials, sock_info)
  File "C:\Users\Armstromg\Anaconda3\lib\site-packages\pymongo\auth.py", line 201, in _authenticate_scram_sha1
    res = sock_info.command(source, cmd)
  File "C:\Users\Armstromg\Anaconda3\lib\site-packages\pymongo\pool.py", line 419, in command
    collation=collation)
  File "C:\Users\Armstromg\Anaconda3\lib\site-packages\pymongo\network.py", line 116, in command
    parse_write_concern_error=parse_write_concern_error)
  File "C:\Users\Armstromg\Anaconda3\lib\site-packages\pymongo\helpers.py", line 210, in _check_command_response
    raise OperationFailure(msg % errmsg, code, response)
pymongo.errors.OperationFailure: Authentication failed.
2018-03-16 14:57:02,323 [Thread-5:80592] [django.request:118] [exception:handle_uncaught_exception] [ERROR]- Internal Server Error: /
Traceback (most recent call last):
  File "C:\Users\Armstromg\Anaconda3\lib\site-packages\django\template\base.py", line 767, in __init__
    self.literal = float(var)
ValueError: could not convert string to float: 'inforday._id'

During handling of the above exception, another exception occurred:

Traceback (most recent call last):
  File "C:\Users\Armstromg\Anaconda3\lib\site-packages\django\template\base.py", line 788, in __init__
    self.literal = mark_safe(unescape_string_literal(var))
  File "C:\Users\Armstromg\Anaconda3\lib\site-packages\django\utils\functional.py", line 196, in wrapper
    return func(*args, **kwargs)
  File "C:\Users\Armstromg\Anaconda3\lib\site-packages\django\utils\text.py", line 397, in unescape_string_literal
    raise ValueError("Not a string literal: %r" % s)
ValueError: Not a string literal: 'inforday._id'

During handling of the above exception, another exception occurred:

Traceback (most recent call last):
  File "C:\Users\Armstromg\Anaconda3\lib\site-packages\django\core\handlers\exception.py", line 35, in inner
    response = get_response(request)
  File "C:\Users\Armstromg\Anaconda3\lib\site-packages\django\core\handlers\base.py", line 128, in _get_response
    response = self.process_exception_by_middleware(e, request)
  File "C:\Users\Armstromg\Anaconda3\lib\site-packages\django\core\handlers\base.py", line 126, in _get_response
    response = wrapped_callback(request, *callback_args, **callback_kwargs)
  File "D:\lilanqing\Project_local\python\maizixueyuan\django-web\bitcs_project\bitcs\views.py", line 16, in index
    return render(request, 'index.html', locals())
  File "C:\Users\Armstromg\Anaconda3\lib\site-packages\django\shortcuts.py", line 36, in render
    content = loader.render_to_string(template_name, context, request, using=using)
  File "C:\Users\Armstromg\Anaconda3\lib\site-packages\django\template\loader.py", line 61, in render_to_string
    template = get_template(template_name, using=using)
  File "C:\Users\Armstromg\Anaconda3\lib\site-packages\django\template\loader.py", line 15, in get_template
    return engine.get_template(template_name)
  File "C:\Users\Armstromg\Anaconda3\lib\site-packages\django\template\backends\django.py", line 34, in get_template
    return Template(self.engine.get_template(template_name), self)
  File "C:\Users\Armstromg\Anaconda3\lib\site-packages\django\template\engine.py", line 144, in get_template
    template, origin = self.find_template(template_name)
  File "C:\Users\Armstromg\Anaconda3\lib\site-packages\django\template\engine.py", line 126, in find_template
    template = loader.get_template(name, skip=skip)
  File "C:\Users\Armstromg\Anaconda3\lib\site-packages\django\template\loaders\base.py", line 30, in get_template
    contents, origin, origin.template_name, self.engine,
  File "C:\Users\Armstromg\Anaconda3\lib\site-packages\django\template\base.py", line 160, in __init__
    self.nodelist = self.compile_nodelist()
  File "C:\Users\Armstromg\Anaconda3\lib\site-packages\django\template\base.py", line 198, in compile_nodelist
    return parser.parse()
  File "C:\Users\Armstromg\Anaconda3\lib\site-packages\django\template\base.py", line 483, in parse
    raise self.error(token, e)
  File "C:\Users\Armstromg\Anaconda3\lib\site-packages\django\template\base.py", line 481, in parse
    compiled_result = compile_func(self, token)
  File "C:\Users\Armstromg\Anaconda3\lib\site-packages\django\template\defaulttags.py", line 815, in do_for
    nodelist_loop = parser.parse(('empty', 'endfor',))
  File "C:\Users\Armstromg\Anaconda3\lib\site-packages\django\template\base.py", line 454, in parse
    raise self.error(token, e)
  File "C:\Users\Armstromg\Anaconda3\lib\site-packages\django\template\base.py", line 452, in parse
    filter_expression = self.compile_filter(token.contents)
  File "C:\Users\Armstromg\Anaconda3\lib\site-packages\django\template\base.py", line 568, in compile_filter
    return FilterExpression(token, self)
  File "C:\Users\Armstromg\Anaconda3\lib\site-packages\django\template\base.py", line 653, in __init__
    var_obj = Variable(var)
  File "C:\Users\Armstromg\Anaconda3\lib\site-packages\django\template\base.py", line 795, in __init__
    var)
django.template.exceptions.TemplateSyntaxError: Variables and attributes may not begin with underscores: 'inforday._id'
2018-03-16 14:57:48,264 [Thread-8:80548] [django.request:118] [exception:handle_uncaught_exception] [ERROR]- Internal Server Error: /
Traceback (most recent call last):
  File "C:\Users\Armstromg\Anaconda3\lib\site-packages\django\template\base.py", line 767, in __init__
    self.literal = float(var)
ValueError: could not convert string to float: 'inforday._id'

During handling of the above exception, another exception occurred:

Traceback (most recent call last):
  File "C:\Users\Armstromg\Anaconda3\lib\site-packages\django\template\base.py", line 788, in __init__
    self.literal = mark_safe(unescape_string_literal(var))
  File "C:\Users\Armstromg\Anaconda3\lib\site-packages\django\utils\functional.py", line 196, in wrapper
    return func(*args, **kwargs)
  File "C:\Users\Armstromg\Anaconda3\lib\site-packages\django\utils\text.py", line 397, in unescape_string_literal
    raise ValueError("Not a string literal: %r" % s)
ValueError: Not a string literal: 'inforday._id'

During handling of the above exception, another exception occurred:

Traceback (most recent call last):
  File "C:\Users\Armstromg\Anaconda3\lib\site-packages\django\core\handlers\exception.py", line 35, in inner
    response = get_response(request)
  File "C:\Users\Armstromg\Anaconda3\lib\site-packages\django\core\handlers\base.py", line 128, in _get_response
    response = self.process_exception_by_middleware(e, request)
  File "C:\Users\Armstromg\Anaconda3\lib\site-packages\django\core\handlers\base.py", line 126, in _get_response
    response = wrapped_callback(request, *callback_args, **callback_kwargs)
  File "D:\lilanqing\Project_local\python\maizixueyuan\django-web\bitcs_project\bitcs\views.py", line 16, in index
    return render(request, 'index.html', locals())
  File "C:\Users\Armstromg\Anaconda3\lib\site-packages\django\shortcuts.py", line 36, in render
    content = loader.render_to_string(template_name, context, request, using=using)
  File "C:\Users\Armstromg\Anaconda3\lib\site-packages\django\template\loader.py", line 61, in render_to_string
    template = get_template(template_name, using=using)
  File "C:\Users\Armstromg\Anaconda3\lib\site-packages\django\template\loader.py", line 15, in get_template
    return engine.get_template(template_name)
  File "C:\Users\Armstromg\Anaconda3\lib\site-packages\django\template\backends\django.py", line 34, in get_template
    return Template(self.engine.get_template(template_name), self)
  File "C:\Users\Armstromg\Anaconda3\lib\site-packages\django\template\engine.py", line 144, in get_template
    template, origin = self.find_template(template_name)
  File "C:\Users\Armstromg\Anaconda3\lib\site-packages\django\template\engine.py", line 126, in find_template
    template = loader.get_template(name, skip=skip)
  File "C:\Users\Armstromg\Anaconda3\lib\site-packages\django\template\loaders\base.py", line 30, in get_template
    contents, origin, origin.template_name, self.engine,
  File "C:\Users\Armstromg\Anaconda3\lib\site-packages\django\template\base.py", line 160, in __init__
    self.nodelist = self.compile_nodelist()
  File "C:\Users\Armstromg\Anaconda3\lib\site-packages\django\template\base.py", line 198, in compile_nodelist
    return parser.parse()
  File "C:\Users\Armstromg\Anaconda3\lib\site-packages\django\template\base.py", line 483, in parse
    raise self.error(token, e)
  File "C:\Users\Armstromg\Anaconda3\lib\site-packages\django\template\base.py", line 481, in parse
    compiled_result = compile_func(self, token)
  File "C:\Users\Armstromg\Anaconda3\lib\site-packages\django\template\defaulttags.py", line 815, in do_for
    nodelist_loop = parser.parse(('empty', 'endfor',))
  File "C:\Users\Armstromg\Anaconda3\lib\site-packages\django\template\base.py", line 454, in parse
    raise self.error(token, e)
  File "C:\Users\Armstromg\Anaconda3\lib\site-packages\django\template\base.py", line 452, in parse
    filter_expression = self.compile_filter(token.contents)
  File "C:\Users\Armstromg\Anaconda3\lib\site-packages\django\template\base.py", line 568, in compile_filter
    return FilterExpression(token, self)
  File "C:\Users\Armstromg\Anaconda3\lib\site-packages\django\template\base.py", line 653, in __init__
    var_obj = Variable(var)
  File "C:\Users\Armstromg\Anaconda3\lib\site-packages\django\template\base.py", line 795, in __init__
    var)
django.template.exceptions.TemplateSyntaxError: Variables and attributes may not begin with underscores: 'inforday._id'
2018-03-16 14:59:18,664 [Thread-1:75732] [django.request:118] [exception:handle_uncaught_exception] [ERROR]- Internal Server Error: /
Traceback (most recent call last):
  File "C:\Users\Armstromg\Anaconda3\lib\site-packages\django\template\base.py", line 767, in __init__
    self.literal = float(var)
ValueError: could not convert string to float: 'inforday._id'

During handling of the above exception, another exception occurred:

Traceback (most recent call last):
  File "C:\Users\Armstromg\Anaconda3\lib\site-packages\django\template\base.py", line 788, in __init__
    self.literal = mark_safe(unescape_string_literal(var))
  File "C:\Users\Armstromg\Anaconda3\lib\site-packages\django\utils\functional.py", line 196, in wrapper
    return func(*args, **kwargs)
  File "C:\Users\Armstromg\Anaconda3\lib\site-packages\django\utils\text.py", line 397, in unescape_string_literal
    raise ValueError("Not a string literal: %r" % s)
ValueError: Not a string literal: 'inforday._id'

During handling of the above exception, another exception occurred:

Traceback (most recent call last):
  File "C:\Users\Armstromg\Anaconda3\lib\site-packages\django\core\handlers\exception.py", line 35, in inner
    response = get_response(request)
  File "C:\Users\Armstromg\Anaconda3\lib\site-packages\django\core\handlers\base.py", line 128, in _get_response
    response = self.process_exception_by_middleware(e, request)
  File "C:\Users\Armstromg\Anaconda3\lib\site-packages\django\core\handlers\base.py", line 126, in _get_response
    response = wrapped_callback(request, *callback_args, **callback_kwargs)
  File "D:\lilanqing\Project_local\python\maizixueyuan\django-web\bitcs_project\bitcs\views.py", line 16, in index
    return render(request, 'index.html', locals())
  File "C:\Users\Armstromg\Anaconda3\lib\site-packages\django\shortcuts.py", line 36, in render
    content = loader.render_to_string(template_name, context, request, using=using)
  File "C:\Users\Armstromg\Anaconda3\lib\site-packages\django\template\loader.py", line 61, in render_to_string
    template = get_template(template_name, using=using)
  File "C:\Users\Armstromg\Anaconda3\lib\site-packages\django\template\loader.py", line 15, in get_template
    return engine.get_template(template_name)
  File "C:\Users\Armstromg\Anaconda3\lib\site-packages\django\template\backends\django.py", line 34, in get_template
    return Template(self.engine.get_template(template_name), self)
  File "C:\Users\Armstromg\Anaconda3\lib\site-packages\django\template\engine.py", line 144, in get_template
    template, origin = self.find_template(template_name)
  File "C:\Users\Armstromg\Anaconda3\lib\site-packages\django\template\engine.py", line 126, in find_template
    template = loader.get_template(name, skip=skip)
  File "C:\Users\Armstromg\Anaconda3\lib\site-packages\django\template\loaders\base.py", line 30, in get_template
    contents, origin, origin.template_name, self.engine,
  File "C:\Users\Armstromg\Anaconda3\lib\site-packages\django\template\base.py", line 160, in __init__
    self.nodelist = self.compile_nodelist()
  File "C:\Users\Armstromg\Anaconda3\lib\site-packages\django\template\base.py", line 198, in compile_nodelist
    return parser.parse()
  File "C:\Users\Armstromg\Anaconda3\lib\site-packages\django\template\base.py", line 483, in parse
    raise self.error(token, e)
  File "C:\Users\Armstromg\Anaconda3\lib\site-packages\django\template\base.py", line 481, in parse
    compiled_result = compile_func(self, token)
  File "C:\Users\Armstromg\Anaconda3\lib\site-packages\django\template\defaulttags.py", line 815, in do_for
    nodelist_loop = parser.parse(('empty', 'endfor',))
  File "C:\Users\Armstromg\Anaconda3\lib\site-packages\django\template\base.py", line 454, in parse
    raise self.error(token, e)
  File "C:\Users\Armstromg\Anaconda3\lib\site-packages\django\template\base.py", line 452, in parse
    filter_expression = self.compile_filter(token.contents)
  File "C:\Users\Armstromg\Anaconda3\lib\site-packages\django\template\base.py", line 568, in compile_filter
    return FilterExpression(token, self)
  File "C:\Users\Armstromg\Anaconda3\lib\site-packages\django\template\base.py", line 653, in __init__
    var_obj = Variable(var)
  File "C:\Users\Armstromg\Anaconda3\lib\site-packages\django\template\base.py", line 795, in __init__
    var)
django.template.exceptions.TemplateSyntaxError: Variables and attributes may not begin with underscores: 'inforday._id'
2018-03-16 14:59:25,434 [Thread-3:77788] [django.request:118] [exception:handle_uncaught_exception] [ERROR]- Internal Server Error: /
Traceback (most recent call last):
  File "C:\Users\Armstromg\Anaconda3\lib\site-packages\django\template\base.py", line 767, in __init__
    self.literal = float(var)
ValueError: could not convert string to float: 'inforday._id'

During handling of the above exception, another exception occurred:

Traceback (most recent call last):
  File "C:\Users\Armstromg\Anaconda3\lib\site-packages\django\template\base.py", line 788, in __init__
    self.literal = mark_safe(unescape_string_literal(var))
  File "C:\Users\Armstromg\Anaconda3\lib\site-packages\django\utils\functional.py", line 196, in wrapper
    return func(*args, **kwargs)
  File "C:\Users\Armstromg\Anaconda3\lib\site-packages\django\utils\text.py", line 397, in unescape_string_literal
    raise ValueError("Not a string literal: %r" % s)
ValueError: Not a string literal: 'inforday._id'

During handling of the above exception, another exception occurred:

Traceback (most recent call last):
  File "C:\Users\Armstromg\Anaconda3\lib\site-packages\django\core\handlers\exception.py", line 35, in inner
    response = get_response(request)
  File "C:\Users\Armstromg\Anaconda3\lib\site-packages\django\core\handlers\base.py", line 128, in _get_response
    response = self.process_exception_by_middleware(e, request)
  File "C:\Users\Armstromg\Anaconda3\lib\site-packages\django\core\handlers\base.py", line 126, in _get_response
    response = wrapped_callback(request, *callback_args, **callback_kwargs)
  File "D:\lilanqing\Project_local\python\maizixueyuan\django-web\bitcs_project\bitcs\views.py", line 16, in index
    return render(request, 'index.html', locals())
  File "C:\Users\Armstromg\Anaconda3\lib\site-packages\django\shortcuts.py", line 36, in render
    content = loader.render_to_string(template_name, context, request, using=using)
  File "C:\Users\Armstromg\Anaconda3\lib\site-packages\django\template\loader.py", line 61, in render_to_string
    template = get_template(template_name, using=using)
  File "C:\Users\Armstromg\Anaconda3\lib\site-packages\django\template\loader.py", line 15, in get_template
    return engine.get_template(template_name)
  File "C:\Users\Armstromg\Anaconda3\lib\site-packages\django\template\backends\django.py", line 34, in get_template
    return Template(self.engine.get_template(template_name), self)
  File "C:\Users\Armstromg\Anaconda3\lib\site-packages\django\template\engine.py", line 144, in get_template
    template, origin = self.find_template(template_name)
  File "C:\Users\Armstromg\Anaconda3\lib\site-packages\django\template\engine.py", line 126, in find_template
    template = loader.get_template(name, skip=skip)
  File "C:\Users\Armstromg\Anaconda3\lib\site-packages\django\template\loaders\base.py", line 30, in get_template
    contents, origin, origin.template_name, self.engine,
  File "C:\Users\Armstromg\Anaconda3\lib\site-packages\django\template\base.py", line 160, in __init__
    self.nodelist = self.compile_nodelist()
  File "C:\Users\Armstromg\Anaconda3\lib\site-packages\django\template\base.py", line 198, in compile_nodelist
    return parser.parse()
  File "C:\Users\Armstromg\Anaconda3\lib\site-packages\django\template\base.py", line 483, in parse
    raise self.error(token, e)
  File "C:\Users\Armstromg\Anaconda3\lib\site-packages\django\template\base.py", line 481, in parse
    compiled_result = compile_func(self, token)
  File "C:\Users\Armstromg\Anaconda3\lib\site-packages\django\template\defaulttags.py", line 815, in do_for
    nodelist_loop = parser.parse(('empty', 'endfor',))
  File "C:\Users\Armstromg\Anaconda3\lib\site-packages\django\template\base.py", line 454, in parse
    raise self.error(token, e)
  File "C:\Users\Armstromg\Anaconda3\lib\site-packages\django\template\base.py", line 452, in parse
    filter_expression = self.compile_filter(token.contents)
  File "C:\Users\Armstromg\Anaconda3\lib\site-packages\django\template\base.py", line 568, in compile_filter
    return FilterExpression(token, self)
  File "C:\Users\Armstromg\Anaconda3\lib\site-packages\django\template\base.py", line 653, in __init__
    var_obj = Variable(var)
  File "C:\Users\Armstromg\Anaconda3\lib\site-packages\django\template\base.py", line 795, in __init__
    var)
django.template.exceptions.TemplateSyntaxError: Variables and attributes may not begin with underscores: 'inforday._id'
2018-03-16 15:00:05,114 [Thread-4:80908] [django.request:118] [exception:handle_uncaught_exception] [ERROR]- Internal Server Error: /
Traceback (most recent call last):
  File "C:\Users\Armstromg\Anaconda3\lib\site-packages\django\template\base.py", line 767, in __init__
    self.literal = float(var)
ValueError: could not convert string to float: 'inforday._id'

During handling of the above exception, another exception occurred:

Traceback (most recent call last):
  File "C:\Users\Armstromg\Anaconda3\lib\site-packages\django\template\base.py", line 788, in __init__
    self.literal = mark_safe(unescape_string_literal(var))
  File "C:\Users\Armstromg\Anaconda3\lib\site-packages\django\utils\functional.py", line 196, in wrapper
    return func(*args, **kwargs)
  File "C:\Users\Armstromg\Anaconda3\lib\site-packages\django\utils\text.py", line 397, in unescape_string_literal
    raise ValueError("Not a string literal: %r" % s)
ValueError: Not a string literal: 'inforday._id'

During handling of the above exception, another exception occurred:

Traceback (most recent call last):
  File "C:\Users\Armstromg\Anaconda3\lib\site-packages\django\core\handlers\exception.py", line 35, in inner
    response = get_response(request)
  File "C:\Users\Armstromg\Anaconda3\lib\site-packages\django\core\handlers\base.py", line 128, in _get_response
    response = self.process_exception_by_middleware(e, request)
  File "C:\Users\Armstromg\Anaconda3\lib\site-packages\django\core\handlers\base.py", line 126, in _get_response
    response = wrapped_callback(request, *callback_args, **callback_kwargs)
  File "D:\lilanqing\Project_local\python\maizixueyuan\django-web\bitcs_project\bitcs\views.py", line 16, in index
    return render(request, 'index.html', locals())
  File "C:\Users\Armstromg\Anaconda3\lib\site-packages\django\shortcuts.py", line 36, in render
    content = loader.render_to_string(template_name, context, request, using=using)
  File "C:\Users\Armstromg\Anaconda3\lib\site-packages\django\template\loader.py", line 61, in render_to_string
    template = get_template(template_name, using=using)
  File "C:\Users\Armstromg\Anaconda3\lib\site-packages\django\template\loader.py", line 15, in get_template
    return engine.get_template(template_name)
  File "C:\Users\Armstromg\Anaconda3\lib\site-packages\django\template\backends\django.py", line 34, in get_template
    return Template(self.engine.get_template(template_name), self)
  File "C:\Users\Armstromg\Anaconda3\lib\site-packages\django\template\engine.py", line 144, in get_template
    template, origin = self.find_template(template_name)
  File "C:\Users\Armstromg\Anaconda3\lib\site-packages\django\template\engine.py", line 126, in find_template
    template = loader.get_template(name, skip=skip)
  File "C:\Users\Armstromg\Anaconda3\lib\site-packages\django\template\loaders\base.py", line 30, in get_template
    contents, origin, origin.template_name, self.engine,
  File "C:\Users\Armstromg\Anaconda3\lib\site-packages\django\template\base.py", line 160, in __init__
    self.nodelist = self.compile_nodelist()
  File "C:\Users\Armstromg\Anaconda3\lib\site-packages\django\template\base.py", line 198, in compile_nodelist
    return parser.parse()
  File "C:\Users\Armstromg\Anaconda3\lib\site-packages\django\template\base.py", line 483, in parse
    raise self.error(token, e)
  File "C:\Users\Armstromg\Anaconda3\lib\site-packages\django\template\base.py", line 481, in parse
    compiled_result = compile_func(self, token)
  File "C:\Users\Armstromg\Anaconda3\lib\site-packages\django\template\defaulttags.py", line 815, in do_for
    nodelist_loop = parser.parse(('empty', 'endfor',))
  File "C:\Users\Armstromg\Anaconda3\lib\site-packages\django\template\base.py", line 454, in parse
    raise self.error(token, e)
  File "C:\Users\Armstromg\Anaconda3\lib\site-packages\django\template\base.py", line 452, in parse
    filter_expression = self.compile_filter(token.contents)
  File "C:\Users\Armstromg\Anaconda3\lib\site-packages\django\template\base.py", line 568, in compile_filter
    return FilterExpression(token, self)
  File "C:\Users\Armstromg\Anaconda3\lib\site-packages\django\template\base.py", line 653, in __init__
    var_obj = Variable(var)
  File "C:\Users\Armstromg\Anaconda3\lib\site-packages\django\template\base.py", line 795, in __init__
    var)
django.template.exceptions.TemplateSyntaxError: Variables and attributes may not begin with underscores: 'inforday._id'
2018-03-16 15:00:07,569 [Thread-5:81008] [django.request:118] [exception:handle_uncaught_exception] [ERROR]- Internal Server Error: /
Traceback (most recent call last):
  File "C:\Users\Armstromg\Anaconda3\lib\site-packages\django\template\base.py", line 767, in __init__
    self.literal = float(var)
ValueError: could not convert string to float: 'inforday._id'

During handling of the above exception, another exception occurred:

Traceback (most recent call last):
  File "C:\Users\Armstromg\Anaconda3\lib\site-packages\django\template\base.py", line 788, in __init__
    self.literal = mark_safe(unescape_string_literal(var))
  File "C:\Users\Armstromg\Anaconda3\lib\site-packages\django\utils\functional.py", line 196, in wrapper
    return func(*args, **kwargs)
  File "C:\Users\Armstromg\Anaconda3\lib\site-packages\django\utils\text.py", line 397, in unescape_string_literal
    raise ValueError("Not a string literal: %r" % s)
ValueError: Not a string literal: 'inforday._id'

During handling of the above exception, another exception occurred:

Traceback (most recent call last):
  File "C:\Users\Armstromg\Anaconda3\lib\site-packages\django\core\handlers\exception.py", line 35, in inner
    response = get_response(request)
  File "C:\Users\Armstromg\Anaconda3\lib\site-packages\django\core\handlers\base.py", line 128, in _get_response
    response = self.process_exception_by_middleware(e, request)
  File "C:\Users\Armstromg\Anaconda3\lib\site-packages\django\core\handlers\base.py", line 126, in _get_response
    response = wrapped_callback(request, *callback_args, **callback_kwargs)
  File "D:\lilanqing\Project_local\python\maizixueyuan\django-web\bitcs_project\bitcs\views.py", line 16, in index
    return render(request, 'index.html', locals())
  File "C:\Users\Armstromg\Anaconda3\lib\site-packages\django\shortcuts.py", line 36, in render
    content = loader.render_to_string(template_name, context, request, using=using)
  File "C:\Users\Armstromg\Anaconda3\lib\site-packages\django\template\loader.py", line 61, in render_to_string
    template = get_template(template_name, using=using)
  File "C:\Users\Armstromg\Anaconda3\lib\site-packages\django\template\loader.py", line 15, in get_template
    return engine.get_template(template_name)
  File "C:\Users\Armstromg\Anaconda3\lib\site-packages\django\template\backends\django.py", line 34, in get_template
    return Template(self.engine.get_template(template_name), self)
  File "C:\Users\Armstromg\Anaconda3\lib\site-packages\django\template\engine.py", line 144, in get_template
    template, origin = self.find_template(template_name)
  File "C:\Users\Armstromg\Anaconda3\lib\site-packages\django\template\engine.py", line 126, in find_template
    template = loader.get_template(name, skip=skip)
  File "C:\Users\Armstromg\Anaconda3\lib\site-packages\django\template\loaders\base.py", line 30, in get_template
    contents, origin, origin.template_name, self.engine,
  File "C:\Users\Armstromg\Anaconda3\lib\site-packages\django\template\base.py", line 160, in __init__
    self.nodelist = self.compile_nodelist()
  File "C:\Users\Armstromg\Anaconda3\lib\site-packages\django\template\base.py", line 198, in compile_nodelist
    return parser.parse()
  File "C:\Users\Armstromg\Anaconda3\lib\site-packages\django\template\base.py", line 483, in parse
    raise self.error(token, e)
  File "C:\Users\Armstromg\Anaconda3\lib\site-packages\django\template\base.py", line 481, in parse
    compiled_result = compile_func(self, token)
  File "C:\Users\Armstromg\Anaconda3\lib\site-packages\django\template\defaulttags.py", line 815, in do_for
    nodelist_loop = parser.parse(('empty', 'endfor',))
  File "C:\Users\Armstromg\Anaconda3\lib\site-packages\django\template\base.py", line 454, in parse
    raise self.error(token, e)
  File "C:\Users\Armstromg\Anaconda3\lib\site-packages\django\template\base.py", line 452, in parse
    filter_expression = self.compile_filter(token.contents)
  File "C:\Users\Armstromg\Anaconda3\lib\site-packages\django\template\base.py", line 568, in compile_filter
    return FilterExpression(token, self)
  File "C:\Users\Armstromg\Anaconda3\lib\site-packages\django\template\base.py", line 653, in __init__
    var_obj = Variable(var)
  File "C:\Users\Armstromg\Anaconda3\lib\site-packages\django\template\base.py", line 795, in __init__
    var)
django.template.exceptions.TemplateSyntaxError: Variables and attributes may not begin with underscores: 'inforday._id'
2018-03-16 15:00:13,915 [Thread-6:81196] [django.request:118] [exception:handle_uncaught_exception] [ERROR]- Internal Server Error: /
Traceback (most recent call last):
  File "C:\Users\Armstromg\Anaconda3\lib\site-packages\django\template\base.py", line 767, in __init__
    self.literal = float(var)
ValueError: could not convert string to float: 'inforday._id'

During handling of the above exception, another exception occurred:

Traceback (most recent call last):
  File "C:\Users\Armstromg\Anaconda3\lib\site-packages\django\template\base.py", line 788, in __init__
    self.literal = mark_safe(unescape_string_literal(var))
  File "C:\Users\Armstromg\Anaconda3\lib\site-packages\django\utils\functional.py", line 196, in wrapper
    return func(*args, **kwargs)
  File "C:\Users\Armstromg\Anaconda3\lib\site-packages\django\utils\text.py", line 397, in unescape_string_literal
    raise ValueError("Not a string literal: %r" % s)
ValueError: Not a string literal: 'inforday._id'

During handling of the above exception, another exception occurred:

Traceback (most recent call last):
  File "C:\Users\Armstromg\Anaconda3\lib\site-packages\django\core\handlers\exception.py", line 35, in inner
    response = get_response(request)
  File "C:\Users\Armstromg\Anaconda3\lib\site-packages\django\core\handlers\base.py", line 128, in _get_response
    response = self.process_exception_by_middleware(e, request)
  File "C:\Users\Armstromg\Anaconda3\lib\site-packages\django\core\handlers\base.py", line 126, in _get_response
    response = wrapped_callback(request, *callback_args, **callback_kwargs)
  File "D:\lilanqing\Project_local\python\maizixueyuan\django-web\bitcs_project\bitcs\views.py", line 16, in index
    return render(request, 'index.html', locals())
  File "C:\Users\Armstromg\Anaconda3\lib\site-packages\django\shortcuts.py", line 36, in render
    content = loader.render_to_string(template_name, context, request, using=using)
  File "C:\Users\Armstromg\Anaconda3\lib\site-packages\django\template\loader.py", line 61, in render_to_string
    template = get_template(template_name, using=using)
  File "C:\Users\Armstromg\Anaconda3\lib\site-packages\django\template\loader.py", line 15, in get_template
    return engine.get_template(template_name)
  File "C:\Users\Armstromg\Anaconda3\lib\site-packages\django\template\backends\django.py", line 34, in get_template
    return Template(self.engine.get_template(template_name), self)
  File "C:\Users\Armstromg\Anaconda3\lib\site-packages\django\template\engine.py", line 144, in get_template
    template, origin = self.find_template(template_name)
  File "C:\Users\Armstromg\Anaconda3\lib\site-packages\django\template\engine.py", line 126, in find_template
    template = loader.get_template(name, skip=skip)
  File "C:\Users\Armstromg\Anaconda3\lib\site-packages\django\template\loaders\base.py", line 30, in get_template
    contents, origin, origin.template_name, self.engine,
  File "C:\Users\Armstromg\Anaconda3\lib\site-packages\django\template\base.py", line 160, in __init__
    self.nodelist = self.compile_nodelist()
  File "C:\Users\Armstromg\Anaconda3\lib\site-packages\django\template\base.py", line 198, in compile_nodelist
    return parser.parse()
  File "C:\Users\Armstromg\Anaconda3\lib\site-packages\django\template\base.py", line 483, in parse
    raise self.error(token, e)
  File "C:\Users\Armstromg\Anaconda3\lib\site-packages\django\template\base.py", line 481, in parse
    compiled_result = compile_func(self, token)
  File "C:\Users\Armstromg\Anaconda3\lib\site-packages\django\template\defaulttags.py", line 815, in do_for
    nodelist_loop = parser.parse(('empty', 'endfor',))
  File "C:\Users\Armstromg\Anaconda3\lib\site-packages\django\template\base.py", line 454, in parse
    raise self.error(token, e)
  File "C:\Users\Armstromg\Anaconda3\lib\site-packages\django\template\base.py", line 452, in parse
    filter_expression = self.compile_filter(token.contents)
  File "C:\Users\Armstromg\Anaconda3\lib\site-packages\django\template\base.py", line 568, in compile_filter
    return FilterExpression(token, self)
  File "C:\Users\Armstromg\Anaconda3\lib\site-packages\django\template\base.py", line 653, in __init__
    var_obj = Variable(var)
  File "C:\Users\Armstromg\Anaconda3\lib\site-packages\django\template\base.py", line 795, in __init__
    var)
django.template.exceptions.TemplateSyntaxError: Variables and attributes may not begin with underscores: 'inforday._id'
2018-03-16 15:11:20,755 [Thread-1:83652] [django.request:118] [exception:handle_uncaught_exception] [ERROR]- Internal Server Error: /
Traceback (most recent call last):
  File "C:\Users\Armstromg\Anaconda3\lib\site-packages\django\template\base.py", line 767, in __init__
    self.literal = float(var)
ValueError: could not convert string to float: 'inforday._id'

During handling of the above exception, another exception occurred:

Traceback (most recent call last):
  File "C:\Users\Armstromg\Anaconda3\lib\site-packages\django\template\base.py", line 788, in __init__
    self.literal = mark_safe(unescape_string_literal(var))
  File "C:\Users\Armstromg\Anaconda3\lib\site-packages\django\utils\functional.py", line 196, in wrapper
    return func(*args, **kwargs)
  File "C:\Users\Armstromg\Anaconda3\lib\site-packages\django\utils\text.py", line 397, in unescape_string_literal
    raise ValueError("Not a string literal: %r" % s)
ValueError: Not a string literal: 'inforday._id'

During handling of the above exception, another exception occurred:

Traceback (most recent call last):
  File "C:\Users\Armstromg\Anaconda3\lib\site-packages\django\core\handlers\exception.py", line 35, in inner
    response = get_response(request)
  File "C:\Users\Armstromg\Anaconda3\lib\site-packages\django\core\handlers\base.py", line 128, in _get_response
    response = self.process_exception_by_middleware(e, request)
  File "C:\Users\Armstromg\Anaconda3\lib\site-packages\django\core\handlers\base.py", line 126, in _get_response
    response = wrapped_callback(request, *callback_args, **callback_kwargs)
  File "D:\lilanqing\Project_local\python\maizixueyuan\django-web\bitcs_project\bitcs\views.py", line 16, in index
    return render(request, 'index.html', locals())
  File "C:\Users\Armstromg\Anaconda3\lib\site-packages\django\shortcuts.py", line 36, in render
    content = loader.render_to_string(template_name, context, request, using=using)
  File "C:\Users\Armstromg\Anaconda3\lib\site-packages\django\template\loader.py", line 61, in render_to_string
    template = get_template(template_name, using=using)
  File "C:\Users\Armstromg\Anaconda3\lib\site-packages\django\template\loader.py", line 15, in get_template
    return engine.get_template(template_name)
  File "C:\Users\Armstromg\Anaconda3\lib\site-packages\django\template\backends\django.py", line 34, in get_template
    return Template(self.engine.get_template(template_name), self)
  File "C:\Users\Armstromg\Anaconda3\lib\site-packages\django\template\engine.py", line 144, in get_template
    template, origin = self.find_template(template_name)
  File "C:\Users\Armstromg\Anaconda3\lib\site-packages\django\template\engine.py", line 126, in find_template
    template = loader.get_template(name, skip=skip)
  File "C:\Users\Armstromg\Anaconda3\lib\site-packages\django\template\loaders\base.py", line 30, in get_template
    contents, origin, origin.template_name, self.engine,
  File "C:\Users\Armstromg\Anaconda3\lib\site-packages\django\template\base.py", line 160, in __init__
    self.nodelist = self.compile_nodelist()
  File "C:\Users\Armstromg\Anaconda3\lib\site-packages\django\template\base.py", line 198, in compile_nodelist
    return parser.parse()
  File "C:\Users\Armstromg\Anaconda3\lib\site-packages\django\template\base.py", line 483, in parse
    raise self.error(token, e)
  File "C:\Users\Armstromg\Anaconda3\lib\site-packages\django\template\base.py", line 481, in parse
    compiled_result = compile_func(self, token)
  File "C:\Users\Armstromg\Anaconda3\lib\site-packages\django\template\defaulttags.py", line 815, in do_for
    nodelist_loop = parser.parse(('empty', 'endfor',))
  File "C:\Users\Armstromg\Anaconda3\lib\site-packages\django\template\base.py", line 454, in parse
    raise self.error(token, e)
  File "C:\Users\Armstromg\Anaconda3\lib\site-packages\django\template\base.py", line 452, in parse
    filter_expression = self.compile_filter(token.contents)
  File "C:\Users\Armstromg\Anaconda3\lib\site-packages\django\template\base.py", line 568, in compile_filter
    return FilterExpression(token, self)
  File "C:\Users\Armstromg\Anaconda3\lib\site-packages\django\template\base.py", line 653, in __init__
    var_obj = Variable(var)
  File "C:\Users\Armstromg\Anaconda3\lib\site-packages\django\template\base.py", line 795, in __init__
    var)
django.template.exceptions.TemplateSyntaxError: Variables and attributes may not begin with underscores: 'inforday._id'
2018-03-16 15:11:23,057 [Thread-3:83396] [django.request:118] [exception:handle_uncaught_exception] [ERROR]- Internal Server Error: /
Traceback (most recent call last):
  File "C:\Users\Armstromg\Anaconda3\lib\site-packages\django\template\base.py", line 767, in __init__
    self.literal = float(var)
ValueError: could not convert string to float: 'inforday._id'

During handling of the above exception, another exception occurred:

Traceback (most recent call last):
  File "C:\Users\Armstromg\Anaconda3\lib\site-packages\django\template\base.py", line 788, in __init__
    self.literal = mark_safe(unescape_string_literal(var))
  File "C:\Users\Armstromg\Anaconda3\lib\site-packages\django\utils\functional.py", line 196, in wrapper
    return func(*args, **kwargs)
  File "C:\Users\Armstromg\Anaconda3\lib\site-packages\django\utils\text.py", line 397, in unescape_string_literal
    raise ValueError("Not a string literal: %r" % s)
ValueError: Not a string literal: 'inforday._id'

During handling of the above exception, another exception occurred:

Traceback (most recent call last):
  File "C:\Users\Armstromg\Anaconda3\lib\site-packages\django\core\handlers\exception.py", line 35, in inner
    response = get_response(request)
  File "C:\Users\Armstromg\Anaconda3\lib\site-packages\django\core\handlers\base.py", line 128, in _get_response
    response = self.process_exception_by_middleware(e, request)
  File "C:\Users\Armstromg\Anaconda3\lib\site-packages\django\core\handlers\base.py", line 126, in _get_response
    response = wrapped_callback(request, *callback_args, **callback_kwargs)
  File "D:\lilanqing\Project_local\python\maizixueyuan\django-web\bitcs_project\bitcs\views.py", line 16, in index
    return render(request, 'index.html', locals())
  File "C:\Users\Armstromg\Anaconda3\lib\site-packages\django\shortcuts.py", line 36, in render
    content = loader.render_to_string(template_name, context, request, using=using)
  File "C:\Users\Armstromg\Anaconda3\lib\site-packages\django\template\loader.py", line 61, in render_to_string
    template = get_template(template_name, using=using)
  File "C:\Users\Armstromg\Anaconda3\lib\site-packages\django\template\loader.py", line 15, in get_template
    return engine.get_template(template_name)
  File "C:\Users\Armstromg\Anaconda3\lib\site-packages\django\template\backends\django.py", line 34, in get_template
    return Template(self.engine.get_template(template_name), self)
  File "C:\Users\Armstromg\Anaconda3\lib\site-packages\django\template\engine.py", line 144, in get_template
    template, origin = self.find_template(template_name)
  File "C:\Users\Armstromg\Anaconda3\lib\site-packages\django\template\engine.py", line 126, in find_template
    template = loader.get_template(name, skip=skip)
  File "C:\Users\Armstromg\Anaconda3\lib\site-packages\django\template\loaders\base.py", line 30, in get_template
    contents, origin, origin.template_name, self.engine,
  File "C:\Users\Armstromg\Anaconda3\lib\site-packages\django\template\base.py", line 160, in __init__
    self.nodelist = self.compile_nodelist()
  File "C:\Users\Armstromg\Anaconda3\lib\site-packages\django\template\base.py", line 198, in compile_nodelist
    return parser.parse()
  File "C:\Users\Armstromg\Anaconda3\lib\site-packages\django\template\base.py", line 483, in parse
    raise self.error(token, e)
  File "C:\Users\Armstromg\Anaconda3\lib\site-packages\django\template\base.py", line 481, in parse
    compiled_result = compile_func(self, token)
  File "C:\Users\Armstromg\Anaconda3\lib\site-packages\django\template\defaulttags.py", line 815, in do_for
    nodelist_loop = parser.parse(('empty', 'endfor',))
  File "C:\Users\Armstromg\Anaconda3\lib\site-packages\django\template\base.py", line 454, in parse
    raise self.error(token, e)
  File "C:\Users\Armstromg\Anaconda3\lib\site-packages\django\template\base.py", line 452, in parse
    filter_expression = self.compile_filter(token.contents)
  File "C:\Users\Armstromg\Anaconda3\lib\site-packages\django\template\base.py", line 568, in compile_filter
    return FilterExpression(token, self)
  File "C:\Users\Armstromg\Anaconda3\lib\site-packages\django\template\base.py", line 653, in __init__
    var_obj = Variable(var)
  File "C:\Users\Armstromg\Anaconda3\lib\site-packages\django\template\base.py", line 795, in __init__
    var)
django.template.exceptions.TemplateSyntaxError: Variables and attributes may not begin with underscores: 'inforday._id'
2018-03-16 15:12:02,834 [Thread-4:82188] [django.request:118] [exception:handle_uncaught_exception] [ERROR]- Internal Server Error: /
Traceback (most recent call last):
  File "C:\Users\Armstromg\Anaconda3\lib\site-packages\django\core\handlers\exception.py", line 35, in inner
    response = get_response(request)
  File "C:\Users\Armstromg\Anaconda3\lib\site-packages\django\core\handlers\base.py", line 128, in _get_response
    response = self.process_exception_by_middleware(e, request)
  File "C:\Users\Armstromg\Anaconda3\lib\site-packages\django\core\handlers\base.py", line 126, in _get_response
    response = wrapped_callback(request, *callback_args, **callback_kwargs)
  File "D:\lilanqing\Project_local\python\maizixueyuan\django-web\bitcs_project\bitcs\views.py", line 16, in index
    return render(request, 'index.html', locals())
  File "C:\Users\Armstromg\Anaconda3\lib\site-packages\django\shortcuts.py", line 36, in render
    content = loader.render_to_string(template_name, context, request, using=using)
  File "C:\Users\Armstromg\Anaconda3\lib\site-packages\django\template\loader.py", line 61, in render_to_string
    template = get_template(template_name, using=using)
  File "C:\Users\Armstromg\Anaconda3\lib\site-packages\django\template\loader.py", line 15, in get_template
    return engine.get_template(template_name)
  File "C:\Users\Armstromg\Anaconda3\lib\site-packages\django\template\backends\django.py", line 34, in get_template
    return Template(self.engine.get_template(template_name), self)
  File "C:\Users\Armstromg\Anaconda3\lib\site-packages\django\template\engine.py", line 144, in get_template
    template, origin = self.find_template(template_name)
  File "C:\Users\Armstromg\Anaconda3\lib\site-packages\django\template\engine.py", line 126, in find_template
    template = loader.get_template(name, skip=skip)
  File "C:\Users\Armstromg\Anaconda3\lib\site-packages\django\template\loaders\base.py", line 30, in get_template
    contents, origin, origin.template_name, self.engine,
  File "C:\Users\Armstromg\Anaconda3\lib\site-packages\django\template\base.py", line 160, in __init__
    self.nodelist = self.compile_nodelist()
  File "C:\Users\Armstromg\Anaconda3\lib\site-packages\django\template\base.py", line 198, in compile_nodelist
    return parser.parse()
  File "C:\Users\Armstromg\Anaconda3\lib\site-packages\django\template\base.py", line 483, in parse
    raise self.error(token, e)
  File "C:\Users\Armstromg\Anaconda3\lib\site-packages\django\template\base.py", line 481, in parse
    compiled_result = compile_func(self, token)
  File "C:\Users\Armstromg\Anaconda3\lib\site-packages\django\template\defaulttags.py", line 815, in do_for
    nodelist_loop = parser.parse(('empty', 'endfor',))
  File "C:\Users\Armstromg\Anaconda3\lib\site-packages\django\template\base.py", line 454, in parse
    raise self.error(token, e)
  File "C:\Users\Armstromg\Anaconda3\lib\site-packages\django\template\base.py", line 452, in parse
    filter_expression = self.compile_filter(token.contents)
  File "C:\Users\Armstromg\Anaconda3\lib\site-packages\django\template\base.py", line 568, in compile_filter
    return FilterExpression(token, self)
  File "C:\Users\Armstromg\Anaconda3\lib\site-packages\django\template\base.py", line 662, in __init__
    filter_func = parser.find_filter(filter_name)
  File "C:\Users\Armstromg\Anaconda3\lib\site-packages\django\template\base.py", line 574, in find_filter
    raise TemplateSyntaxError("Invalid filter: '%s'" % filter_name)
django.template.exceptions.TemplateSyntaxError: Invalid filter: 'private'
2018-03-16 15:14:30,371 [Thread-5:83044] [django.request:118] [exception:handle_uncaught_exception] [ERROR]- Internal Server Error: /
Traceback (most recent call last):
  File "C:\Users\Armstromg\Anaconda3\lib\site-packages\django\template\defaulttags.py", line 1025, in find_library
    return parser.libraries[name]
KeyError: 'myfilt'

During handling of the above exception, another exception occurred:

Traceback (most recent call last):
  File "C:\Users\Armstromg\Anaconda3\lib\site-packages\django\core\handlers\exception.py", line 35, in inner
    response = get_response(request)
  File "C:\Users\Armstromg\Anaconda3\lib\site-packages\django\core\handlers\base.py", line 128, in _get_response
    response = self.process_exception_by_middleware(e, request)
  File "C:\Users\Armstromg\Anaconda3\lib\site-packages\django\core\handlers\base.py", line 126, in _get_response
    response = wrapped_callback(request, *callback_args, **callback_kwargs)
  File "D:\lilanqing\Project_local\python\maizixueyuan\django-web\bitcs_project\bitcs\views.py", line 16, in index
    return render(request, 'index.html', locals())
  File "C:\Users\Armstromg\Anaconda3\lib\site-packages\django\shortcuts.py", line 36, in render
    content = loader.render_to_string(template_name, context, request, using=using)
  File "C:\Users\Armstromg\Anaconda3\lib\site-packages\django\template\loader.py", line 61, in render_to_string
    template = get_template(template_name, using=using)
  File "C:\Users\Armstromg\Anaconda3\lib\site-packages\django\template\loader.py", line 15, in get_template
    return engine.get_template(template_name)
  File "C:\Users\Armstromg\Anaconda3\lib\site-packages\django\template\backends\django.py", line 34, in get_template
    return Template(self.engine.get_template(template_name), self)
  File "C:\Users\Armstromg\Anaconda3\lib\site-packages\django\template\engine.py", line 144, in get_template
    template, origin = self.find_template(template_name)
  File "C:\Users\Armstromg\Anaconda3\lib\site-packages\django\template\engine.py", line 126, in find_template
    template = loader.get_template(name, skip=skip)
  File "C:\Users\Armstromg\Anaconda3\lib\site-packages\django\template\loaders\base.py", line 30, in get_template
    contents, origin, origin.template_name, self.engine,
  File "C:\Users\Armstromg\Anaconda3\lib\site-packages\django\template\base.py", line 160, in __init__
    self.nodelist = self.compile_nodelist()
  File "C:\Users\Armstromg\Anaconda3\lib\site-packages\django\template\base.py", line 198, in compile_nodelist
    return parser.parse()
  File "C:\Users\Armstromg\Anaconda3\lib\site-packages\django\template\base.py", line 483, in parse
    raise self.error(token, e)
  File "C:\Users\Armstromg\Anaconda3\lib\site-packages\django\template\base.py", line 481, in parse
    compiled_result = compile_func(self, token)
  File "C:\Users\Armstromg\Anaconda3\lib\site-packages\django\template\defaulttags.py", line 1082, in load
    lib = find_library(parser, name)
  File "C:\Users\Armstromg\Anaconda3\lib\site-packages\django\template\defaulttags.py", line 1029, in find_library
    name, "\n".join(sorted(parser.libraries)),
django.template.exceptions.TemplateSyntaxError: 'myfilt' is not a registered tag library. Must be one of:
admin_list
admin_modify
admin_static
admin_urls
cache
i18n
l10n
log
static
staticfiles
tz
2018-03-16 15:14:54,312 [Thread-7:83880] [django.request:118] [exception:handle_uncaught_exception] [ERROR]- Internal Server Error: /
Traceback (most recent call last):
  File "C:\Users\Armstromg\Anaconda3\lib\site-packages\django\template\defaulttags.py", line 1025, in find_library
    return parser.libraries[name]
KeyError: 'myfilter'

During handling of the above exception, another exception occurred:

Traceback (most recent call last):
  File "C:\Users\Armstromg\Anaconda3\lib\site-packages\django\core\handlers\exception.py", line 35, in inner
    response = get_response(request)
  File "C:\Users\Armstromg\Anaconda3\lib\site-packages\django\core\handlers\base.py", line 128, in _get_response
    response = self.process_exception_by_middleware(e, request)
  File "C:\Users\Armstromg\Anaconda3\lib\site-packages\django\core\handlers\base.py", line 126, in _get_response
    response = wrapped_callback(request, *callback_args, **callback_kwargs)
  File "D:\lilanqing\Project_local\python\maizixueyuan\django-web\bitcs_project\bitcs\views.py", line 16, in index
    return render(request, 'index.html', locals())
  File "C:\Users\Armstromg\Anaconda3\lib\site-packages\django\shortcuts.py", line 36, in render
    content = loader.render_to_string(template_name, context, request, using=using)
  File "C:\Users\Armstromg\Anaconda3\lib\site-packages\django\template\loader.py", line 61, in render_to_string
    template = get_template(template_name, using=using)
  File "C:\Users\Armstromg\Anaconda3\lib\site-packages\django\template\loader.py", line 15, in get_template
    return engine.get_template(template_name)
  File "C:\Users\Armstromg\Anaconda3\lib\site-packages\django\template\backends\django.py", line 34, in get_template
    return Template(self.engine.get_template(template_name), self)
  File "C:\Users\Armstromg\Anaconda3\lib\site-packages\django\template\engine.py", line 144, in get_template
    template, origin = self.find_template(template_name)
  File "C:\Users\Armstromg\Anaconda3\lib\site-packages\django\template\engine.py", line 126, in find_template
    template = loader.get_template(name, skip=skip)
  File "C:\Users\Armstromg\Anaconda3\lib\site-packages\django\template\loaders\base.py", line 30, in get_template
    contents, origin, origin.template_name, self.engine,
  File "C:\Users\Armstromg\Anaconda3\lib\site-packages\django\template\base.py", line 160, in __init__
    self.nodelist = self.compile_nodelist()
  File "C:\Users\Armstromg\Anaconda3\lib\site-packages\django\template\base.py", line 198, in compile_nodelist
    return parser.parse()
  File "C:\Users\Armstromg\Anaconda3\lib\site-packages\django\template\base.py", line 483, in parse
    raise self.error(token, e)
  File "C:\Users\Armstromg\Anaconda3\lib\site-packages\django\template\base.py", line 481, in parse
    compiled_result = compile_func(self, token)
  File "C:\Users\Armstromg\Anaconda3\lib\site-packages\django\template\defaulttags.py", line 1082, in load
    lib = find_library(parser, name)
  File "C:\Users\Armstromg\Anaconda3\lib\site-packages\django\template\defaulttags.py", line 1029, in find_library
    name, "\n".join(sorted(parser.libraries)),
django.template.exceptions.TemplateSyntaxError: 'myfilter' is not a registered tag library. Must be one of:
admin_list
admin_modify
admin_static
admin_urls
cache
i18n
l10n
log
static
staticfiles
tz
2018-03-16 15:15:34,121 [Thread-9:84936] [django.request:118] [exception:handle_uncaught_exception] [ERROR]- Internal Server Error: /
Traceback (most recent call last):
  File "C:\Users\Armstromg\Anaconda3\lib\site-packages\django\template\defaulttags.py", line 1025, in find_library
    return parser.libraries[name]
KeyError: 'myfilter'

During handling of the above exception, another exception occurred:

Traceback (most recent call last):
  File "C:\Users\Armstromg\Anaconda3\lib\site-packages\django\core\handlers\exception.py", line 35, in inner
    response = get_response(request)
  File "C:\Users\Armstromg\Anaconda3\lib\site-packages\django\core\handlers\base.py", line 128, in _get_response
    response = self.process_exception_by_middleware(e, request)
  File "C:\Users\Armstromg\Anaconda3\lib\site-packages\django\core\handlers\base.py", line 126, in _get_response
    response = wrapped_callback(request, *callback_args, **callback_kwargs)
  File "D:\lilanqing\Project_local\python\maizixueyuan\django-web\bitcs_project\bitcs\views.py", line 16, in index
    return render(request, 'index.html', locals())
  File "C:\Users\Armstromg\Anaconda3\lib\site-packages\django\shortcuts.py", line 36, in render
    content = loader.render_to_string(template_name, context, request, using=using)
  File "C:\Users\Armstromg\Anaconda3\lib\site-packages\django\template\loader.py", line 61, in render_to_string
    template = get_template(template_name, using=using)
  File "C:\Users\Armstromg\Anaconda3\lib\site-packages\django\template\loader.py", line 15, in get_template
    return engine.get_template(template_name)
  File "C:\Users\Armstromg\Anaconda3\lib\site-packages\django\template\backends\django.py", line 34, in get_template
    return Template(self.engine.get_template(template_name), self)
  File "C:\Users\Armstromg\Anaconda3\lib\site-packages\django\template\engine.py", line 144, in get_template
    template, origin = self.find_template(template_name)
  File "C:\Users\Armstromg\Anaconda3\lib\site-packages\django\template\engine.py", line 126, in find_template
    template = loader.get_template(name, skip=skip)
  File "C:\Users\Armstromg\Anaconda3\lib\site-packages\django\template\loaders\base.py", line 30, in get_template
    contents, origin, origin.template_name, self.engine,
  File "C:\Users\Armstromg\Anaconda3\lib\site-packages\django\template\base.py", line 160, in __init__
    self.nodelist = self.compile_nodelist()
  File "C:\Users\Armstromg\Anaconda3\lib\site-packages\django\template\base.py", line 198, in compile_nodelist
    return parser.parse()
  File "C:\Users\Armstromg\Anaconda3\lib\site-packages\django\template\base.py", line 483, in parse
    raise self.error(token, e)
  File "C:\Users\Armstromg\Anaconda3\lib\site-packages\django\template\base.py", line 481, in parse
    compiled_result = compile_func(self, token)
  File "C:\Users\Armstromg\Anaconda3\lib\site-packages\django\template\defaulttags.py", line 1082, in load
    lib = find_library(parser, name)
  File "C:\Users\Armstromg\Anaconda3\lib\site-packages\django\template\defaulttags.py", line 1029, in find_library
    name, "\n".join(sorted(parser.libraries)),
django.template.exceptions.TemplateSyntaxError: 'myfilter' is not a registered tag library. Must be one of:
admin_list
admin_modify
admin_static
admin_urls
cache
i18n
l10n
log
static
staticfiles
tz
2018-03-16 15:20:57,573 [Thread-11:86176] [django.request:118] [exception:handle_uncaught_exception] [ERROR]- Internal Server Error: /
Traceback (most recent call last):
  File "C:\Users\Armstromg\Anaconda3\lib\site-packages\django\template\defaulttags.py", line 1025, in find_library
    return parser.libraries[name]
KeyError: 'myfilter'

During handling of the above exception, another exception occurred:

Traceback (most recent call last):
  File "C:\Users\Armstromg\Anaconda3\lib\site-packages\django\core\handlers\exception.py", line 35, in inner
    response = get_response(request)
  File "C:\Users\Armstromg\Anaconda3\lib\site-packages\django\core\handlers\base.py", line 128, in _get_response
    response = self.process_exception_by_middleware(e, request)
  File "C:\Users\Armstromg\Anaconda3\lib\site-packages\django\core\handlers\base.py", line 126, in _get_response
    response = wrapped_callback(request, *callback_args, **callback_kwargs)
  File "D:\lilanqing\Project_local\python\maizixueyuan\django-web\bitcs_project\bitcs\views.py", line 16, in index
    return render(request, 'index.html', locals())
  File "C:\Users\Armstromg\Anaconda3\lib\site-packages\django\shortcuts.py", line 36, in render
    content = loader.render_to_string(template_name, context, request, using=using)
  File "C:\Users\Armstromg\Anaconda3\lib\site-packages\django\template\loader.py", line 61, in render_to_string
    template = get_template(template_name, using=using)
  File "C:\Users\Armstromg\Anaconda3\lib\site-packages\django\template\loader.py", line 15, in get_template
    return engine.get_template(template_name)
  File "C:\Users\Armstromg\Anaconda3\lib\site-packages\django\template\backends\django.py", line 34, in get_template
    return Template(self.engine.get_template(template_name), self)
  File "C:\Users\Armstromg\Anaconda3\lib\site-packages\django\template\engine.py", line 144, in get_template
    template, origin = self.find_template(template_name)
  File "C:\Users\Armstromg\Anaconda3\lib\site-packages\django\template\engine.py", line 126, in find_template
    template = loader.get_template(name, skip=skip)
  File "C:\Users\Armstromg\Anaconda3\lib\site-packages\django\template\loaders\base.py", line 30, in get_template
    contents, origin, origin.template_name, self.engine,
  File "C:\Users\Armstromg\Anaconda3\lib\site-packages\django\template\base.py", line 160, in __init__
    self.nodelist = self.compile_nodelist()
  File "C:\Users\Armstromg\Anaconda3\lib\site-packages\django\template\base.py", line 198, in compile_nodelist
    return parser.parse()
  File "C:\Users\Armstromg\Anaconda3\lib\site-packages\django\template\base.py", line 483, in parse
    raise self.error(token, e)
  File "C:\Users\Armstromg\Anaconda3\lib\site-packages\django\template\base.py", line 481, in parse
    compiled_result = compile_func(self, token)
  File "C:\Users\Armstromg\Anaconda3\lib\site-packages\django\template\defaulttags.py", line 1082, in load
    lib = find_library(parser, name)
  File "C:\Users\Armstromg\Anaconda3\lib\site-packages\django\template\defaulttags.py", line 1029, in find_library
    name, "\n".join(sorted(parser.libraries)),
django.template.exceptions.TemplateSyntaxError: 'myfilter' is not a registered tag library. Must be one of:
admin_list
admin_modify
admin_static
admin_urls
cache
i18n
l10n
log
static
staticfiles
tz
2018-03-16 15:21:11,519 [Thread-1:86596] [django.request:118] [exception:handle_uncaught_exception] [ERROR]- Internal Server Error: /
Traceback (most recent call last):
  File "C:\Users\Armstromg\Anaconda3\lib\site-packages\django\core\handlers\exception.py", line 35, in inner
    response = get_response(request)
  File "C:\Users\Armstromg\Anaconda3\lib\site-packages\django\core\handlers\base.py", line 128, in _get_response
    response = self.process_exception_by_middleware(e, request)
  File "C:\Users\Armstromg\Anaconda3\lib\site-packages\django\core\handlers\base.py", line 126, in _get_response
    response = wrapped_callback(request, *callback_args, **callback_kwargs)
  File "D:\lilanqing\Project_local\python\maizixueyuan\django-web\bitcs_project\bitcs\views.py", line 16, in index
    return render(request, 'index.html', locals())
  File "C:\Users\Armstromg\Anaconda3\lib\site-packages\django\shortcuts.py", line 36, in render
    content = loader.render_to_string(template_name, context, request, using=using)
  File "C:\Users\Armstromg\Anaconda3\lib\site-packages\django\template\loader.py", line 62, in render_to_string
    return template.render(context, request)
  File "C:\Users\Armstromg\Anaconda3\lib\site-packages\django\template\backends\django.py", line 61, in render
    return self.template.render(context)
  File "C:\Users\Armstromg\Anaconda3\lib\site-packages\django\template\base.py", line 175, in render
    return self._render(context)
  File "C:\Users\Armstromg\Anaconda3\lib\site-packages\django\template\base.py", line 167, in _render
    return self.nodelist.render(context)
  File "C:\Users\Armstromg\Anaconda3\lib\site-packages\django\template\base.py", line 943, in render
    bit = node.render_annotated(context)
  File "C:\Users\Armstromg\Anaconda3\lib\site-packages\django\template\base.py", line 910, in render_annotated
    return self.render(context)
  File "C:\Users\Armstromg\Anaconda3\lib\site-packages\django\template\defaulttags.py", line 168, in render
    len_values = len(values)
  File "C:\Users\Armstromg\Anaconda3\lib\site-packages\django\core\paginator.py", line 141, in __len__
    return len(self.object_list)
  File "C:\Users\Armstromg\Anaconda3\lib\site-packages\mongoengine\queryset\queryset.py", line 51, in __len__
    list(self._iter_results())
  File "C:\Users\Armstromg\Anaconda3\lib\site-packages\mongoengine\queryset\queryset.py", line 99, in _iter_results
    self._populate_cache()
  File "C:\Users\Armstromg\Anaconda3\lib\site-packages\mongoengine\queryset\queryset.py", line 118, in _populate_cache
    self._result_cache.append(next(self))
  File "C:\Users\Armstromg\Anaconda3\lib\site-packages\mongoengine\queryset\base.py", line 1473, in __next__
    only_fields=self.only_fields)
  File "C:\Users\Armstromg\Anaconda3\lib\site-packages\mongoengine\base\document.py", line 704, in _from_son
    else field.to_python(value))
  File "C:\Users\Armstromg\Anaconda3\lib\site-packages\mongoengine\fields.py", line 268, in to_python
    value = int(value)
TypeError: int() argument must be a string, a bytes-like object or a number, not 'ObjectId'
2018-03-16 15:24:11,748 [Thread-4:86028] [django.request:118] [exception:handle_uncaught_exception] [ERROR]- Internal Server Error: /
Traceback (most recent call last):
  File "C:\Users\Armstromg\Anaconda3\lib\site-packages\django\template\base.py", line 767, in __init__
    self.literal = float(var)
ValueError: could not convert string to float: 'inforday._id'

During handling of the above exception, another exception occurred:

Traceback (most recent call last):
  File "C:\Users\Armstromg\Anaconda3\lib\site-packages\django\template\base.py", line 788, in __init__
    self.literal = mark_safe(unescape_string_literal(var))
  File "C:\Users\Armstromg\Anaconda3\lib\site-packages\django\utils\functional.py", line 196, in wrapper
    return func(*args, **kwargs)
  File "C:\Users\Armstromg\Anaconda3\lib\site-packages\django\utils\text.py", line 397, in unescape_string_literal
    raise ValueError("Not a string literal: %r" % s)
ValueError: Not a string literal: 'inforday._id'

During handling of the above exception, another exception occurred:

Traceback (most recent call last):
  File "C:\Users\Armstromg\Anaconda3\lib\site-packages\django\core\handlers\exception.py", line 35, in inner
    response = get_response(request)
  File "C:\Users\Armstromg\Anaconda3\lib\site-packages\django\core\handlers\base.py", line 128, in _get_response
    response = self.process_exception_by_middleware(e, request)
  File "C:\Users\Armstromg\Anaconda3\lib\site-packages\django\core\handlers\base.py", line 126, in _get_response
    response = wrapped_callback(request, *callback_args, **callback_kwargs)
  File "D:\lilanqing\Project_local\python\maizixueyuan\django-web\bitcs_project\bitcs\views.py", line 16, in index
    return render(request, 'index.html', locals())
  File "C:\Users\Armstromg\Anaconda3\lib\site-packages\django\shortcuts.py", line 36, in render
    content = loader.render_to_string(template_name, context, request, using=using)
  File "C:\Users\Armstromg\Anaconda3\lib\site-packages\django\template\loader.py", line 61, in render_to_string
    template = get_template(template_name, using=using)
  File "C:\Users\Armstromg\Anaconda3\lib\site-packages\django\template\loader.py", line 15, in get_template
    return engine.get_template(template_name)
  File "C:\Users\Armstromg\Anaconda3\lib\site-packages\django\template\backends\django.py", line 34, in get_template
    return Template(self.engine.get_template(template_name), self)
  File "C:\Users\Armstromg\Anaconda3\lib\site-packages\django\template\engine.py", line 144, in get_template
    template, origin = self.find_template(template_name)
  File "C:\Users\Armstromg\Anaconda3\lib\site-packages\django\template\engine.py", line 126, in find_template
    template = loader.get_template(name, skip=skip)
  File "C:\Users\Armstromg\Anaconda3\lib\site-packages\django\template\loaders\base.py", line 30, in get_template
    contents, origin, origin.template_name, self.engine,
  File "C:\Users\Armstromg\Anaconda3\lib\site-packages\django\template\base.py", line 160, in __init__
    self.nodelist = self.compile_nodelist()
  File "C:\Users\Armstromg\Anaconda3\lib\site-packages\django\template\base.py", line 198, in compile_nodelist
    return parser.parse()
  File "C:\Users\Armstromg\Anaconda3\lib\site-packages\django\template\base.py", line 483, in parse
    raise self.error(token, e)
  File "C:\Users\Armstromg\Anaconda3\lib\site-packages\django\template\base.py", line 481, in parse
    compiled_result = compile_func(self, token)
  File "C:\Users\Armstromg\Anaconda3\lib\site-packages\django\template\defaulttags.py", line 815, in do_for
    nodelist_loop = parser.parse(('empty', 'endfor',))
  File "C:\Users\Armstromg\Anaconda3\lib\site-packages\django\template\base.py", line 454, in parse
    raise self.error(token, e)
  File "C:\Users\Armstromg\Anaconda3\lib\site-packages\django\template\base.py", line 452, in parse
    filter_expression = self.compile_filter(token.contents)
  File "C:\Users\Armstromg\Anaconda3\lib\site-packages\django\template\base.py", line 568, in compile_filter
    return FilterExpression(token, self)
  File "C:\Users\Armstromg\Anaconda3\lib\site-packages\django\template\base.py", line 653, in __init__
    var_obj = Variable(var)
  File "C:\Users\Armstromg\Anaconda3\lib\site-packages\django\template\base.py", line 795, in __init__
    var)
django.template.exceptions.TemplateSyntaxError: Variables and attributes may not begin with underscores: 'inforday._id'
2018-03-16 15:24:33,610 [Thread-6:84452] [django.request:118] [exception:handle_uncaught_exception] [ERROR]- Internal Server Error: /
Traceback (most recent call last):
  File "C:\Users\Armstromg\Anaconda3\lib\site-packages\django\core\handlers\exception.py", line 35, in inner
    response = get_response(request)
  File "C:\Users\Armstromg\Anaconda3\lib\site-packages\django\core\handlers\base.py", line 128, in _get_response
    response = self.process_exception_by_middleware(e, request)
  File "C:\Users\Armstromg\Anaconda3\lib\site-packages\django\core\handlers\base.py", line 126, in _get_response
    response = wrapped_callback(request, *callback_args, **callback_kwargs)
  File "D:\lilanqing\Project_local\python\maizixueyuan\django-web\bitcs_project\bitcs\views.py", line 16, in index
    return render(request, 'index.html', locals())
  File "C:\Users\Armstromg\Anaconda3\lib\site-packages\django\shortcuts.py", line 36, in render
    content = loader.render_to_string(template_name, context, request, using=using)
  File "C:\Users\Armstromg\Anaconda3\lib\site-packages\django\template\loader.py", line 62, in render_to_string
    return template.render(context, request)
  File "C:\Users\Armstromg\Anaconda3\lib\site-packages\django\template\backends\django.py", line 61, in render
    return self.template.render(context)
  File "C:\Users\Armstromg\Anaconda3\lib\site-packages\django\template\base.py", line 175, in render
    return self._render(context)
  File "C:\Users\Armstromg\Anaconda3\lib\site-packages\django\template\base.py", line 167, in _render
    return self.nodelist.render(context)
  File "C:\Users\Armstromg\Anaconda3\lib\site-packages\django\template\base.py", line 943, in render
    bit = node.render_annotated(context)
  File "C:\Users\Armstromg\Anaconda3\lib\site-packages\django\template\base.py", line 910, in render_annotated
    return self.render(context)
  File "C:\Users\Armstromg\Anaconda3\lib\site-packages\django\template\defaulttags.py", line 168, in render
    len_values = len(values)
  File "C:\Users\Armstromg\Anaconda3\lib\site-packages\django\core\paginator.py", line 141, in __len__
    return len(self.object_list)
  File "C:\Users\Armstromg\Anaconda3\lib\site-packages\mongoengine\queryset\queryset.py", line 51, in __len__
    list(self._iter_results())
  File "C:\Users\Armstromg\Anaconda3\lib\site-packages\mongoengine\queryset\queryset.py", line 99, in _iter_results
    self._populate_cache()
  File "C:\Users\Armstromg\Anaconda3\lib\site-packages\mongoengine\queryset\queryset.py", line 118, in _populate_cache
    self._result_cache.append(next(self))
  File "C:\Users\Armstromg\Anaconda3\lib\site-packages\mongoengine\queryset\base.py", line 1473, in __next__
    only_fields=self.only_fields)
  File "C:\Users\Armstromg\Anaconda3\lib\site-packages\mongoengine\base\document.py", line 704, in _from_son
    else field.to_python(value))
  File "C:\Users\Armstromg\Anaconda3\lib\site-packages\mongoengine\fields.py", line 268, in to_python
    value = int(value)
TypeError: int() argument must be a string, a bytes-like object or a number, not 'ObjectId'
2018-03-16 15:25:37,994 [Thread-5:87792] [django.request:93] [base:get_response] [WARNING]- Not Found: /detailPage.html
2018-03-16 15:31:28,320 [Thread-3:88980] [django.request:93] [base:get_response] [WARNING]- Not Found: /detailPage.html
2018-03-16 15:32:29,803 [Thread-1:87896] [django.request:93] [base:get_response] [WARNING]- Not Found: /detailPage.html
2018-03-16 15:33:38,418 [Thread-5:86376] [django.request:93] [base:get_response] [WARNING]- Not Found: /detailPage.html
2018-03-16 15:33:39,703 [Thread-6:7712] [django.request:93] [base:get_response] [WARNING]- Not Found: /detailPage.html
2018-03-16 15:33:44,795 [Thread-7:83124] [django.request:93] [base:get_response] [WARNING]- Not Found: /detailPage.html
2018-03-16 15:34:30,101 [Thread-1:89640] [django.request:118] [exception:handle_uncaught_exception] [ERROR]- Internal Server Error: /detailPage/
Traceback (most recent call last):
  File "C:\Users\Armstromg\Anaconda3\lib\site-packages\django\core\handlers\exception.py", line 35, in inner
    response = get_response(request)
  File "C:\Users\Armstromg\Anaconda3\lib\site-packages\django\core\handlers\base.py", line 128, in _get_response
    response = self.process_exception_by_middleware(e, request)
  File "C:\Users\Armstromg\Anaconda3\lib\site-packages\django\core\handlers\base.py", line 126, in _get_response
    response = wrapped_callback(request, *callback_args, **callback_kwargs)
  File "D:\lilanqing\Project_local\python\maizixueyuan\django-web\bitcs_project\bitcs\views.py", line 21, in detailPage
    print(news.title)
AttributeError: 'QuerySet' object has no attribute 'title'
2018-03-16 15:36:59,051 [Thread-4:89128] [django.request:118] [exception:handle_uncaught_exception] [ERROR]- Internal Server Error: /detailPage/
Traceback (most recent call last):
  File "C:\Users\Armstromg\Anaconda3\lib\site-packages\django\core\handlers\exception.py", line 35, in inner
    response = get_response(request)
  File "C:\Users\Armstromg\Anaconda3\lib\site-packages\django\core\handlers\base.py", line 128, in _get_response
    response = self.process_exception_by_middleware(e, request)
  File "C:\Users\Armstromg\Anaconda3\lib\site-packages\django\core\handlers\base.py", line 126, in _get_response
    response = wrapped_callback(request, *callback_args, **callback_kwargs)
  File "D:\lilanqing\Project_local\python\maizixueyuan\django-web\bitcs_project\bitcs\views.py", line 21, in detailPage
    print(news.title)
AttributeError: 'QuerySet' object has no attribute 'title'
2018-03-16 15:37:48,154 [Thread-5:89496] [django.request:118] [exception:handle_uncaught_exception] [ERROR]- Internal Server Error: /detailPage/
Traceback (most recent call last):
  File "C:\Users\Armstromg\Anaconda3\lib\site-packages\django\core\handlers\exception.py", line 35, in inner
    response = get_response(request)
  File "C:\Users\Armstromg\Anaconda3\lib\site-packages\django\core\handlers\base.py", line 128, in _get_response
    response = self.process_exception_by_middleware(e, request)
  File "C:\Users\Armstromg\Anaconda3\lib\site-packages\django\core\handlers\base.py", line 126, in _get_response
    response = wrapped_callback(request, *callback_args, **callback_kwargs)
  File "D:\lilanqing\Project_local\python\maizixueyuan\django-web\bitcs_project\bitcs\views.py", line 21, in detailPage
    print(news.title)
AttributeError: 'QuerySet' object has no attribute 'title'
2018-03-16 15:37:50,186 [Thread-6:7428] [django.request:118] [exception:handle_uncaught_exception] [ERROR]- Internal Server Error: /detailPage/
Traceback (most recent call last):
  File "C:\Users\Armstromg\Anaconda3\lib\site-packages\django\core\handlers\exception.py", line 35, in inner
    response = get_response(request)
  File "C:\Users\Armstromg\Anaconda3\lib\site-packages\django\core\handlers\base.py", line 128, in _get_response
    response = self.process_exception_by_middleware(e, request)
  File "C:\Users\Armstromg\Anaconda3\lib\site-packages\django\core\handlers\base.py", line 126, in _get_response
    response = wrapped_callback(request, *callback_args, **callback_kwargs)
  File "D:\lilanqing\Project_local\python\maizixueyuan\django-web\bitcs_project\bitcs\views.py", line 21, in detailPage
    print(news.title)
AttributeError: 'QuerySet' object has no attribute 'title'
2018-03-16 15:37:52,315 [Thread-7:89636] [django.request:118] [exception:handle_uncaught_exception] [ERROR]- Internal Server Error: /detailPage/
Traceback (most recent call last):
  File "C:\Users\Armstromg\Anaconda3\lib\site-packages\django\core\handlers\exception.py", line 35, in inner
    response = get_response(request)
  File "C:\Users\Armstromg\Anaconda3\lib\site-packages\django\core\handlers\base.py", line 128, in _get_response
    response = self.process_exception_by_middleware(e, request)
  File "C:\Users\Armstromg\Anaconda3\lib\site-packages\django\core\handlers\base.py", line 126, in _get_response
    response = wrapped_callback(request, *callback_args, **callback_kwargs)
  File "D:\lilanqing\Project_local\python\maizixueyuan\django-web\bitcs_project\bitcs\views.py", line 21, in detailPage
    print(news.title)
AttributeError: 'QuerySet' object has no attribute 'title'
2018-03-16 15:38:54,312 [Thread-8:91084] [django.request:93] [base:get_response] [WARNING]- Not Found: /favicon.ico
2018-03-16 15:38:55,872 [Thread-10:91120] [django.request:118] [exception:handle_uncaught_exception] [ERROR]- Internal Server Error: /detailPage/
Traceback (most recent call last):
  File "C:\Users\Armstromg\Anaconda3\lib\site-packages\django\core\handlers\exception.py", line 35, in inner
    response = get_response(request)
  File "C:\Users\Armstromg\Anaconda3\lib\site-packages\django\core\handlers\base.py", line 128, in _get_response
    response = self.process_exception_by_middleware(e, request)
  File "C:\Users\Armstromg\Anaconda3\lib\site-packages\django\core\handlers\base.py", line 126, in _get_response
    response = wrapped_callback(request, *callback_args, **callback_kwargs)
  File "D:\lilanqing\Project_local\python\maizixueyuan\django-web\bitcs_project\bitcs\views.py", line 21, in detailPage
    print(news.title)
AttributeError: 'QuerySet' object has no attribute 'title'
2018-03-16 15:39:11,263 [Thread-3:89320] [django.request:118] [exception:handle_uncaught_exception] [ERROR]- Internal Server Error: /detailPage/
Traceback (most recent call last):
  File "C:\Users\Armstromg\Anaconda3\lib\site-packages\django\core\handlers\exception.py", line 35, in inner
    response = get_response(request)
  File "C:\Users\Armstromg\Anaconda3\lib\site-packages\django\core\handlers\base.py", line 128, in _get_response
    response = self.process_exception_by_middleware(e, request)
  File "C:\Users\Armstromg\Anaconda3\lib\site-packages\django\core\handlers\base.py", line 126, in _get_response
    response = wrapped_callback(request, *callback_args, **callback_kwargs)
  File "D:\lilanqing\Project_local\python\maizixueyuan\django-web\bitcs_project\bitcs\views.py", line 21, in detailPage
    print(news.title)
AttributeError: 'QuerySet' object has no attribute 'title'
2018-03-16 15:44:00,512 [Thread-6:91332] [django.request:93] [base:get_response] [WARNING]- Not Found: /detailPage/css/bootstrap.min.css
2018-03-16 15:44:00,547 [Thread-7:91392] [django.request:93] [base:get_response] [WARNING]- Not Found: /detailPage/js/bootstrap.min.js
2018-03-16 15:44:10,758 [Thread-9:91756] [django.request:93] [base:get_response] [WARNING]- Not Found: /detailPage/css/bootstrap.min.css
2018-03-16 15:44:10,797 [Thread-10:89968] [django.request:93] [base:get_response] [WARNING]- Not Found: /detailPage/js/bootstrap.min.js
2018-03-16 15:44:10,851 [Thread-11:91824] [django.request:93] [base:get_response] [WARNING]- Not Found: /detailPage/js/bootstrap.min.js
2018-03-16 15:45:10,966 [Thread-13:89764] [django.request:93] [base:get_response] [WARNING]- Not Found: /detailPage/css/bootstrap.min.css
2018-03-16 15:47:22,288 [Thread-17:92788] [django.request:93] [base:get_response] [WARNING]- Not Found: /detailPage/p
2018-03-16 16:05:33,769 [Thread-3:97244] [django.request:93] [base:get_response] [WARNING]- Not Found: /mainPage.php
2018-03-16 16:05:36,191 [Thread-4:96640] [django.request:93] [base:get_response] [WARNING]- Not Found: /favicon.ico
2018-03-19 09:07:22,279 [Thread-3:4856] [django.request:93] [base:get_response] [WARNING]- Not Found: /favicon.ico
2018-03-19 09:07:52,466 [Thread-6:11144] [django.request:93] [base:get_response] [WARNING]- Not Found: /detailPage/mainPage.php
2018-03-19 09:35:50,037 [Thread-20:17560] [django.request:93] [base:get_response] [WARNING]- Not Found: /index.html
2018-03-19 09:36:42,917 [Thread-1:16144] [django.request:93] [base:get_response] [WARNING]- Not Found: /index.html
2018-03-19 09:57:46,124 [Thread-17:23760] [django.request:93] [base:get_response] [WARNING]- Not Found: /AdvSearchPage.php
2018-03-19 10:08:31,294 [Thread-3:25956] [django.request:118] [exception:handle_uncaught_exception] [ERROR]- Internal Server Error: /advSearchPage
Traceback (most recent call last):
  File "C:\Users\Armstromg\Anaconda3\lib\site-packages\django\core\handlers\exception.py", line 35, in inner
    response = get_response(request)
  File "C:\Users\Armstromg\Anaconda3\lib\site-packages\django\core\handlers\base.py", line 139, in _get_response
    "returned None instead." % (callback.__module__, view_name)
ValueError: The view bitcs.views.advSearchPage didn't return an HttpResponse object. It returned None instead.
2018-03-19 10:15:05,832 [Thread-1:27748] [django.request:118] [exception:handle_uncaught_exception] [ERROR]- Internal Server Error: /index
Traceback (most recent call last):
  File "C:\Users\Armstromg\Anaconda3\lib\site-packages\django\core\handlers\exception.py", line 35, in inner
    response = get_response(request)
  File "C:\Users\Armstromg\Anaconda3\lib\site-packages\django\core\handlers\base.py", line 128, in _get_response
    response = self.process_exception_by_middleware(e, request)
  File "C:\Users\Armstromg\Anaconda3\lib\site-packages\django\core\handlers\base.py", line 126, in _get_response
    response = wrapped_callback(request, *callback_args, **callback_kwargs)
  File "D:\lilanqing\Project_local\python\maizixueyuan\django-web\bitcs_project\bitcs\views.py", line 26, in index
    return render(request, 'index.html', locals())
  File "C:\Users\Armstromg\Anaconda3\lib\site-packages\django\shortcuts.py", line 36, in render
    content = loader.render_to_string(template_name, context, request, using=using)
  File "C:\Users\Armstromg\Anaconda3\lib\site-packages\django\template\loader.py", line 61, in render_to_string
    template = get_template(template_name, using=using)
  File "C:\Users\Armstromg\Anaconda3\lib\site-packages\django\template\loader.py", line 15, in get_template
    return engine.get_template(template_name)
  File "C:\Users\Armstromg\Anaconda3\lib\site-packages\django\template\backends\django.py", line 34, in get_template
    return Template(self.engine.get_template(template_name), self)
  File "C:\Users\Armstromg\Anaconda3\lib\site-packages\django\template\engine.py", line 144, in get_template
    template, origin = self.find_template(template_name)
  File "C:\Users\Armstromg\Anaconda3\lib\site-packages\django\template\engine.py", line 126, in find_template
    template = loader.get_template(name, skip=skip)
  File "C:\Users\Armstromg\Anaconda3\lib\site-packages\django\template\loaders\base.py", line 30, in get_template
    contents, origin, origin.template_name, self.engine,
  File "C:\Users\Armstromg\Anaconda3\lib\site-packages\django\template\base.py", line 160, in __init__
    self.nodelist = self.compile_nodelist()
  File "C:\Users\Armstromg\Anaconda3\lib\site-packages\django\template\base.py", line 198, in compile_nodelist
    return parser.parse()
  File "C:\Users\Armstromg\Anaconda3\lib\site-packages\django\template\base.py", line 483, in parse
    raise self.error(token, e)
  File "C:\Users\Armstromg\Anaconda3\lib\site-packages\django\template\base.py", line 481, in parse
    compiled_result = compile_func(self, token)
  File "C:\Users\Armstromg\Anaconda3\lib\site-packages\django\template\loader_tags.py", line 290, in do_extends
    nodelist = parser.parse()
  File "C:\Users\Armstromg\Anaconda3\lib\site-packages\django\template\base.py", line 483, in parse
    raise self.error(token, e)
  File "C:\Users\Armstromg\Anaconda3\lib\site-packages\django\template\base.py", line 481, in parse
    compiled_result = compile_func(self, token)
  File "C:\Users\Armstromg\Anaconda3\lib\site-packages\django\template\loader_tags.py", line 233, in do_block
    nodelist = parser.parse(('endblock',))
  File "C:\Users\Armstromg\Anaconda3\lib\site-packages\django\template\base.py", line 483, in parse
    raise self.error(token, e)
  File "C:\Users\Armstromg\Anaconda3\lib\site-packages\django\template\base.py", line 481, in parse
    compiled_result = compile_func(self, token)
  File "C:\Users\Armstromg\Anaconda3\lib\site-packages\django\template\defaulttags.py", line 815, in do_for
    nodelist_loop = parser.parse(('empty', 'endfor',))
  File "C:\Users\Armstromg\Anaconda3\lib\site-packages\django\template\base.py", line 454, in parse
    raise self.error(token, e)
  File "C:\Users\Armstromg\Anaconda3\lib\site-packages\django\template\base.py", line 452, in parse
    filter_expression = self.compile_filter(token.contents)
  File "C:\Users\Armstromg\Anaconda3\lib\site-packages\django\template\base.py", line 568, in compile_filter
    return FilterExpression(token, self)
  File "C:\Users\Armstromg\Anaconda3\lib\site-packages\django\template\base.py", line 662, in __init__
    filter_func = parser.find_filter(filter_name)
  File "C:\Users\Armstromg\Anaconda3\lib\site-packages\django\template\base.py", line 574, in find_filter
    raise TemplateSyntaxError("Invalid filter: '%s'" % filter_name)
django.template.exceptions.TemplateSyntaxError: Invalid filter: 'private'
2018-03-19 10:16:01,813 [Thread-12:28036] [django.request:93] [base:get_response] [WARNING]- Not Found: /css/bootstrap.min.css
2018-03-19 10:16:01,829 [Thread-13:28032] [django.request:93] [base:get_response] [WARNING]- Not Found: /js/bootstrap.min.js
2018-03-19 10:16:01,860 [Thread-14:28020] [django.request:93] [base:get_response] [WARNING]- Not Found: /js/bootstrap.min.js
2018-03-19 10:18:04,446 [Thread-19:25556] [django.request:93] [base:get_response] [WARNING]- Not Found: /AdvSearchTestPage.php
2018-03-19 10:22:20,286 [Thread-28:28268] [django.request:93] [base:get_response] [WARNING]- Not Found: /AdvSearchTestPage.php
2018-03-19 10:22:30,264 [Thread-29:28440] [django.request:93] [base:get_response] [WARNING]- Not Found: /get_news_list.php
2018-03-19 10:22:31,190 [Thread-30:29648] [django.request:93] [base:get_response] [WARNING]- Not Found: /get_news_list.php
2018-03-19 12:17:48,179 [Thread-5:57360] [django.request:118] [exception:handle_uncaught_exception] [ERROR]- Internal Server Error: /searchPage
Traceback (most recent call last):
  File "C:\Users\Armstromg\Anaconda3\lib\site-packages\django\core\handlers\exception.py", line 35, in inner
    response = get_response(request)
  File "C:\Users\Armstromg\Anaconda3\lib\site-packages\django\core\handlers\base.py", line 128, in _get_response
    response = self.process_exception_by_middleware(e, request)
  File "C:\Users\Armstromg\Anaconda3\lib\site-packages\django\core\handlers\base.py", line 126, in _get_response
    response = wrapped_callback(request, *callback_args, **callback_kwargs)
  File "D:\lilanqing\Project_local\python\maizixueyuan\django-web\bitcs_project\bitcs\views.py", line 43, in searchPage
    return render(request, 'searchPage.html', locals())
  File "C:\Users\Armstromg\Anaconda3\lib\site-packages\django\shortcuts.py", line 36, in render
    content = loader.render_to_string(template_name, context, request, using=using)
  File "C:\Users\Armstromg\Anaconda3\lib\site-packages\django\template\loader.py", line 61, in render_to_string
    template = get_template(template_name, using=using)
  File "C:\Users\Armstromg\Anaconda3\lib\site-packages\django\template\loader.py", line 15, in get_template
    return engine.get_template(template_name)
  File "C:\Users\Armstromg\Anaconda3\lib\site-packages\django\template\backends\django.py", line 34, in get_template
    return Template(self.engine.get_template(template_name), self)
  File "C:\Users\Armstromg\Anaconda3\lib\site-packages\django\template\engine.py", line 144, in get_template
    template, origin = self.find_template(template_name)
  File "C:\Users\Armstromg\Anaconda3\lib\site-packages\django\template\engine.py", line 126, in find_template
    template = loader.get_template(name, skip=skip)
  File "C:\Users\Armstromg\Anaconda3\lib\site-packages\django\template\loaders\base.py", line 30, in get_template
    contents, origin, origin.template_name, self.engine,
  File "C:\Users\Armstromg\Anaconda3\lib\site-packages\django\template\base.py", line 160, in __init__
    self.nodelist = self.compile_nodelist()
  File "C:\Users\Armstromg\Anaconda3\lib\site-packages\django\template\base.py", line 198, in compile_nodelist
    return parser.parse()
  File "C:\Users\Armstromg\Anaconda3\lib\site-packages\django\template\base.py", line 483, in parse
    raise self.error(token, e)
  File "C:\Users\Armstromg\Anaconda3\lib\site-packages\django\template\base.py", line 481, in parse
    compiled_result = compile_func(self, token)
  File "C:\Users\Armstromg\Anaconda3\lib\site-packages\django\template\loader_tags.py", line 290, in do_extends
    nodelist = parser.parse()
  File "C:\Users\Armstromg\Anaconda3\lib\site-packages\django\template\base.py", line 483, in parse
    raise self.error(token, e)
  File "C:\Users\Armstromg\Anaconda3\lib\site-packages\django\template\base.py", line 481, in parse
    compiled_result = compile_func(self, token)
  File "C:\Users\Armstromg\Anaconda3\lib\site-packages\django\template\loader_tags.py", line 233, in do_block
    nodelist = parser.parse(('endblock',))
  File "C:\Users\Armstromg\Anaconda3\lib\site-packages\django\template\base.py", line 483, in parse
    raise self.error(token, e)
  File "C:\Users\Armstromg\Anaconda3\lib\site-packages\django\template\base.py", line 481, in parse
    compiled_result = compile_func(self, token)
  File "C:\Users\Armstromg\Anaconda3\lib\site-packages\django\template\defaulttags.py", line 815, in do_for
    nodelist_loop = parser.parse(('empty', 'endfor',))
  File "C:\Users\Armstromg\Anaconda3\lib\site-packages\django\template\base.py", line 454, in parse
    raise self.error(token, e)
  File "C:\Users\Armstromg\Anaconda3\lib\site-packages\django\template\base.py", line 452, in parse
    filter_expression = self.compile_filter(token.contents)
  File "C:\Users\Armstromg\Anaconda3\lib\site-packages\django\template\base.py", line 568, in compile_filter
    return FilterExpression(token, self)
  File "C:\Users\Armstromg\Anaconda3\lib\site-packages\django\template\base.py", line 662, in __init__
    filter_func = parser.find_filter(filter_name)
  File "C:\Users\Armstromg\Anaconda3\lib\site-packages\django\template\base.py", line 574, in find_filter
    raise TemplateSyntaxError("Invalid filter: '%s'" % filter_name)
django.template.exceptions.TemplateSyntaxError: Invalid filter: 'private'
2018-03-19 12:25:12,606 [Thread-1:48080] [django.request:93] [base:get_response] [WARNING]- Not Found: /favicon.ico
2018-03-19 12:25:16,846 [Thread-6:58812] [django.request:118] [exception:handle_uncaught_exception] [ERROR]- Internal Server Error: /detailPage/
Traceback (most recent call last):
  File "C:\Users\Armstromg\Anaconda3\lib\site-packages\django\core\handlers\exception.py", line 35, in inner
    response = get_response(request)
  File "C:\Users\Armstromg\Anaconda3\lib\site-packages\django\core\handlers\base.py", line 128, in _get_response
    response = self.process_exception_by_middleware(e, request)
  File "C:\Users\Armstromg\Anaconda3\lib\site-packages\django\core\handlers\base.py", line 126, in _get_response
    response = wrapped_callback(request, *callback_args, **callback_kwargs)
  File "D:\lilanqing\Project_local\python\maizixueyuan\django-web\bitcs_project\bitcs\views.py", line 32, in detailPage
    news.extend(Jimo.objects.filter(_id=_id))
AttributeError: 'QuerySet' object has no attribute 'extend'
2018-03-19 12:32:17,197 [Thread-4:55320] [django.request:118] [exception:handle_uncaught_exception] [ERROR]- Internal Server Error: /detailPage/
Traceback (most recent call last):
  File "C:\Users\Armstromg\Anaconda3\lib\site-packages\django\core\handlers\exception.py", line 35, in inner
    response = get_response(request)
  File "C:\Users\Armstromg\Anaconda3\lib\site-packages\django\core\handlers\base.py", line 128, in _get_response
    response = self.process_exception_by_middleware(e, request)
  File "C:\Users\Armstromg\Anaconda3\lib\site-packages\django\core\handlers\base.py", line 126, in _get_response
    response = wrapped_callback(request, *callback_args, **callback_kwargs)
  File "D:\lilanqing\Project_local\python\maizixueyuan\django-web\bitcs_project\bitcs\views.py", line 33, in detailPage
    news += Jimo.objects.filter(_id=_id)
TypeError: unsupported operand type(s) for +=: 'QuerySet' and 'QuerySet'
2018-03-19 12:41:45,013 [Thread-12:63564] [django.request:93] [base:get_response] [WARNING]- Not Found: /detailPage/mainPage.php
2018-03-19 12:41:52,095 [Thread-13:63752] [django.request:93] [base:get_response] [WARNING]- Not Found: /favicon.ico
2018-03-19 13:04:53,637 [Thread-1:60632] [django.request:118] [exception:handle_uncaught_exception] [ERROR]- Internal Server Error: /detailPage/
Traceback (most recent call last):
  File "C:\Users\Armstromg\Anaconda3\lib\site-packages\django\core\handlers\exception.py", line 35, in inner
    response = get_response(request)
  File "C:\Users\Armstromg\Anaconda3\lib\site-packages\django\core\handlers\base.py", line 128, in _get_response
    response = self.process_exception_by_middleware(e, request)
  File "C:\Users\Armstromg\Anaconda3\lib\site-packages\django\core\handlers\base.py", line 126, in _get_response
    response = wrapped_callback(request, *callback_args, **callback_kwargs)
  File "D:\lilanqing\Project_local\python\maizixueyuan\django-web\bitcs_project\bitcs\views.py", line 32, in detailPage
    news1 = Inforday.objects.filter(_id=_id).only('title', 'content', 'date', 'url')
  File "C:\Users\Armstromg\Anaconda3\lib\site-packages\mongoengine\queryset\base.py", line 902, in only
    return self.fields(True, **fields)
  File "C:\Users\Armstromg\Anaconda3\lib\site-packages\mongoengine\queryset\base.py", line 976, in fields
    fields = queryset._fields_to_dbfields(fields)
  File "C:\Users\Armstromg\Anaconda3\lib\site-packages\mongoengine\queryset\base.py", line 1758, in _fields_to_dbfields
    raise err
  File "C:\Users\Armstromg\Anaconda3\lib\site-packages\mongoengine\queryset\base.py", line 1737, in _fields_to_dbfields
    for f in self._document._lookup_field(field_parts)
  File "C:\Users\Armstromg\Anaconda3\lib\site-packages\mongoengine\base\document.py", line 1008, in _lookup_field
    raise LookUpError('Cannot resolve field "%s"' % field_name)
mongoengine.errors.LookUpError: Cannot resolve field "date"
2018-03-19 13:05:19,830 [Thread-1:69644] [django.request:118] [exception:handle_uncaught_exception] [ERROR]- Internal Server Error: /detailPage/
Traceback (most recent call last):
  File "C:\Users\Armstromg\Anaconda3\lib\site-packages\django\core\handlers\exception.py", line 35, in inner
    response = get_response(request)
  File "C:\Users\Armstromg\Anaconda3\lib\site-packages\django\core\handlers\base.py", line 128, in _get_response
    response = self.process_exception_by_middleware(e, request)
  File "C:\Users\Armstromg\Anaconda3\lib\site-packages\django\core\handlers\base.py", line 126, in _get_response
    response = wrapped_callback(request, *callback_args, **callback_kwargs)
  File "D:\lilanqing\Project_local\python\maizixueyuan\django-web\bitcs_project\bitcs\views.py", line 34, in detailPage
    news3 = Inforconduction.objects.filter(_id=_id).only('title', 'time', 'date', 'url')
  File "C:\Users\Armstromg\Anaconda3\lib\site-packages\mongoengine\queryset\base.py", line 902, in only
    return self.fields(True, **fields)
  File "C:\Users\Armstromg\Anaconda3\lib\site-packages\mongoengine\queryset\base.py", line 976, in fields
    fields = queryset._fields_to_dbfields(fields)
  File "C:\Users\Armstromg\Anaconda3\lib\site-packages\mongoengine\queryset\base.py", line 1758, in _fields_to_dbfields
    raise err
  File "C:\Users\Armstromg\Anaconda3\lib\site-packages\mongoengine\queryset\base.py", line 1737, in _fields_to_dbfields
    for f in self._document._lookup_field(field_parts)
  File "C:\Users\Armstromg\Anaconda3\lib\site-packages\mongoengine\base\document.py", line 1008, in _lookup_field
    raise LookUpError('Cannot resolve field "%s"' % field_name)
mongoengine.errors.LookUpError: Cannot resolve field "date"
2018-03-19 13:05:23,606 [Thread-3:69724] [django.request:118] [exception:handle_uncaught_exception] [ERROR]- Internal Server Error: /detailPage/
Traceback (most recent call last):
  File "C:\Users\Armstromg\Anaconda3\lib\site-packages\django\core\handlers\exception.py", line 35, in inner
    response = get_response(request)
  File "C:\Users\Armstromg\Anaconda3\lib\site-packages\django\core\handlers\base.py", line 128, in _get_response
    response = self.process_exception_by_middleware(e, request)
  File "C:\Users\Armstromg\Anaconda3\lib\site-packages\django\core\handlers\base.py", line 126, in _get_response
    response = wrapped_callback(request, *callback_args, **callback_kwargs)
  File "D:\lilanqing\Project_local\python\maizixueyuan\django-web\bitcs_project\bitcs\views.py", line 34, in detailPage
    news3 = Inforconduction.objects.filter(_id=_id).only('title', 'time', 'date', 'url')
  File "C:\Users\Armstromg\Anaconda3\lib\site-packages\mongoengine\queryset\base.py", line 902, in only
    return self.fields(True, **fields)
  File "C:\Users\Armstromg\Anaconda3\lib\site-packages\mongoengine\queryset\base.py", line 976, in fields
    fields = queryset._fields_to_dbfields(fields)
  File "C:\Users\Armstromg\Anaconda3\lib\site-packages\mongoengine\queryset\base.py", line 1758, in _fields_to_dbfields
    raise err
  File "C:\Users\Armstromg\Anaconda3\lib\site-packages\mongoengine\queryset\base.py", line 1737, in _fields_to_dbfields
    for f in self._document._lookup_field(field_parts)
  File "C:\Users\Armstromg\Anaconda3\lib\site-packages\mongoengine\base\document.py", line 1008, in _lookup_field
    raise LookUpError('Cannot resolve field "%s"' % field_name)
mongoengine.errors.LookUpError: Cannot resolve field "date"
2018-03-19 13:05:26,964 [Thread-4:69764] [django.request:118] [exception:handle_uncaught_exception] [ERROR]- Internal Server Error: /detailPage/
Traceback (most recent call last):
  File "C:\Users\Armstromg\Anaconda3\lib\site-packages\django\core\handlers\exception.py", line 35, in inner
    response = get_response(request)
  File "C:\Users\Armstromg\Anaconda3\lib\site-packages\django\core\handlers\base.py", line 128, in _get_response
    response = self.process_exception_by_middleware(e, request)
  File "C:\Users\Armstromg\Anaconda3\lib\site-packages\django\core\handlers\base.py", line 126, in _get_response
    response = wrapped_callback(request, *callback_args, **callback_kwargs)
  File "D:\lilanqing\Project_local\python\maizixueyuan\django-web\bitcs_project\bitcs\views.py", line 34, in detailPage
    news3 = Inforconduction.objects.filter(_id=_id).only('title', 'time', 'date', 'url')
  File "C:\Users\Armstromg\Anaconda3\lib\site-packages\mongoengine\queryset\base.py", line 902, in only
    return self.fields(True, **fields)
  File "C:\Users\Armstromg\Anaconda3\lib\site-packages\mongoengine\queryset\base.py", line 976, in fields
    fields = queryset._fields_to_dbfields(fields)
  File "C:\Users\Armstromg\Anaconda3\lib\site-packages\mongoengine\queryset\base.py", line 1758, in _fields_to_dbfields
    raise err
  File "C:\Users\Armstromg\Anaconda3\lib\site-packages\mongoengine\queryset\base.py", line 1737, in _fields_to_dbfields
    for f in self._document._lookup_field(field_parts)
  File "C:\Users\Armstromg\Anaconda3\lib\site-packages\mongoengine\base\document.py", line 1008, in _lookup_field
    raise LookUpError('Cannot resolve field "%s"' % field_name)
mongoengine.errors.LookUpError: Cannot resolve field "date"
2018-03-19 13:05:36,599 [Thread-5:70000] [django.request:118] [exception:handle_uncaught_exception] [ERROR]- Internal Server Error: /detailPage/
Traceback (most recent call last):
  File "C:\Users\Armstromg\Anaconda3\lib\site-packages\django\core\handlers\exception.py", line 35, in inner
    response = get_response(request)
  File "C:\Users\Armstromg\Anaconda3\lib\site-packages\django\core\handlers\base.py", line 128, in _get_response
    response = self.process_exception_by_middleware(e, request)
  File "C:\Users\Armstromg\Anaconda3\lib\site-packages\django\core\handlers\base.py", line 126, in _get_response
    response = wrapped_callback(request, *callback_args, **callback_kwargs)
  File "D:\lilanqing\Project_local\python\maizixueyuan\django-web\bitcs_project\bitcs\views.py", line 34, in detailPage
    news3 = Inforconduction.objects.filter(_id=_id).only('title', 'time', 'date', 'url')
  File "C:\Users\Armstromg\Anaconda3\lib\site-packages\mongoengine\queryset\base.py", line 902, in only
    return self.fields(True, **fields)
  File "C:\Users\Armstromg\Anaconda3\lib\site-packages\mongoengine\queryset\base.py", line 976, in fields
    fields = queryset._fields_to_dbfields(fields)
  File "C:\Users\Armstromg\Anaconda3\lib\site-packages\mongoengine\queryset\base.py", line 1758, in _fields_to_dbfields
    raise err
  File "C:\Users\Armstromg\Anaconda3\lib\site-packages\mongoengine\queryset\base.py", line 1737, in _fields_to_dbfields
    for f in self._document._lookup_field(field_parts)
  File "C:\Users\Armstromg\Anaconda3\lib\site-packages\mongoengine\base\document.py", line 1008, in _lookup_field
    raise LookUpError('Cannot resolve field "%s"' % field_name)
mongoengine.errors.LookUpError: Cannot resolve field "date"
2018-03-19 13:05:57,677 [Thread-1:70488] [django.request:118] [exception:handle_uncaught_exception] [ERROR]- Internal Server Error: /detailPage/
Traceback (most recent call last):
  File "C:\Users\Armstromg\Anaconda3\lib\site-packages\django\core\handlers\exception.py", line 35, in inner
    response = get_response(request)
  File "C:\Users\Armstromg\Anaconda3\lib\site-packages\django\core\handlers\base.py", line 128, in _get_response
    response = self.process_exception_by_middleware(e, request)
  File "C:\Users\Armstromg\Anaconda3\lib\site-packages\django\core\handlers\base.py", line 126, in _get_response
    response = wrapped_callback(request, *callback_args, **callback_kwargs)
  File "D:\lilanqing\Project_local\python\maizixueyuan\django-web\bitcs_project\bitcs\views.py", line 36, in detailPage
    news = news1 | news2 | news3
TypeError: unsupported operand type(s) for |: 'QuerySet' and 'QuerySet'
2018-03-19 13:08:14,979 [Thread-1:68928] [django.request:118] [exception:handle_uncaught_exception] [ERROR]- Internal Server Error: /detailPage/
Traceback (most recent call last):
  File "C:\Users\Armstromg\Anaconda3\lib\site-packages\django\core\handlers\exception.py", line 35, in inner
    response = get_response(request)
  File "C:\Users\Armstromg\Anaconda3\lib\site-packages\django\core\handlers\base.py", line 128, in _get_response
    response = self.process_exception_by_middleware(e, request)
  File "C:\Users\Armstromg\Anaconda3\lib\site-packages\django\core\handlers\base.py", line 126, in _get_response
    response = wrapped_callback(request, *callback_args, **callback_kwargs)
  File "D:\lilanqing\Project_local\python\maizixueyuan\django-web\bitcs_project\bitcs\views.py", line 37, in detailPage
    news = news.dintinct()
AttributeError: 'itertools.chain' object has no attribute 'dintinct'
2018-03-19 13:14:32,622 [Thread-1:72408] [django.request:118] [exception:handle_uncaught_exception] [ERROR]- Internal Server Error: /detailPage/
Traceback (most recent call last):
  File "C:\Users\Armstromg\Anaconda3\lib\site-packages\django\core\handlers\exception.py", line 35, in inner
    response = get_response(request)
  File "C:\Users\Armstromg\Anaconda3\lib\site-packages\django\core\handlers\base.py", line 128, in _get_response
    response = self.process_exception_by_middleware(e, request)
  File "C:\Users\Armstromg\Anaconda3\lib\site-packages\django\core\handlers\base.py", line 126, in _get_response
    response = wrapped_callback(request, *callback_args, **callback_kwargs)
  File "D:\lilanqing\Project_local\python\maizixueyuan\django-web\bitcs_project\bitcs\views.py", line 36, in detailPage
    news = news1 | news2 | news3
TypeError: unsupported operand type(s) for |: 'QuerySet' and 'QuerySet'
2018-03-19 13:22:11,360 [Thread-1:74024] [django.request:118] [exception:handle_uncaught_exception] [ERROR]- Internal Server Error: /detailPage/
Traceback (most recent call last):
  File "C:\Users\Armstromg\Anaconda3\lib\site-packages\django\core\handlers\exception.py", line 35, in inner
    response = get_response(request)
  File "C:\Users\Armstromg\Anaconda3\lib\site-packages\django\core\handlers\base.py", line 128, in _get_response
    response = self.process_exception_by_middleware(e, request)
  File "C:\Users\Armstromg\Anaconda3\lib\site-packages\django\core\handlers\base.py", line 126, in _get_response
    response = wrapped_callback(request, *callback_args, **callback_kwargs)
  File "D:\lilanqing\Project_local\python\maizixueyuan\django-web\bitcs_project\bitcs\views.py", line 33, in detailPage
    news2 = Jimo.objects.filter(_id=_id).only('title', 'content', 'time', 'url')[0]
  File "C:\Users\Armstromg\Anaconda3\lib\site-packages\mongoengine\queryset\base.py", line 197, in __getitem__
    queryset._cursor[key],
  File "C:\Users\Armstromg\Anaconda3\lib\site-packages\pymongo\cursor.py", line 570, in __getitem__
    raise IndexError("no such item for Cursor instance")
IndexError: no such item for Cursor instance
2018-03-19 13:26:43,383 [Thread-1:74976] [django.request:118] [exception:handle_uncaught_exception] [ERROR]- Internal Server Error: /detailPage/
Traceback (most recent call last):
  File "C:\Users\Armstromg\Anaconda3\lib\site-packages\django\core\handlers\exception.py", line 35, in inner
    response = get_response(request)
  File "C:\Users\Armstromg\Anaconda3\lib\site-packages\django\core\handlers\base.py", line 128, in _get_response
    response = self.process_exception_by_middleware(e, request)
  File "C:\Users\Armstromg\Anaconda3\lib\site-packages\django\core\handlers\base.py", line 126, in _get_response
    response = wrapped_callback(request, *callback_args, **callback_kwargs)
  File "D:\lilanqing\Project_local\python\maizixueyuan\django-web\bitcs_project\bitcs\views.py", line 36, in detailPage
    news = set(news1, news2, news3)
TypeError: set expected at most 1 arguments, got 3
2018-03-19 13:35:12,501 [Thread-5:77212] [django.request:93] [base:get_response] [WARNING]- Not Found: /detailPage/mainPage.php
2018-03-19 13:37:52,076 [Thread-9:75592] [django.request:93] [base:get_response] [WARNING]- Not Found: /detailPage/index
2018-03-19 13:37:57,386 [Thread-10:77068] [django.request:93] [base:get_response] [WARNING]- Not Found: /detailPage/index
2018-03-19 13:52:40,681 [Thread-1:67608] [django.request:118] [exception:handle_uncaught_exception] [ERROR]- Internal Server Error: /searchPage
Traceback (most recent call last):
  File "C:\Users\Armstromg\Anaconda3\lib\site-packages\django\core\paginator.py", line 85, in count
    return self.object_list.count()
AttributeError: 'itertools.chain' object has no attribute 'count'

During handling of the above exception, another exception occurred:

Traceback (most recent call last):
  File "C:\Users\Armstromg\Anaconda3\lib\site-packages\django\core\handlers\exception.py", line 35, in inner
    response = get_response(request)
  File "C:\Users\Armstromg\Anaconda3\lib\site-packages\django\core\handlers\base.py", line 128, in _get_response
    response = self.process_exception_by_middleware(e, request)
  File "C:\Users\Armstromg\Anaconda3\lib\site-packages\django\core\handlers\base.py", line 126, in _get_response
    response = wrapped_callback(request, *callback_args, **callback_kwargs)
  File "D:\lilanqing\Project_local\python\maizixueyuan\django-web\bitcs_project\bitcs\views.py", line 66, in searchPage
    query_results = paginator.page(page)
  File "C:\Users\Armstromg\Anaconda3\lib\site-packages\django\core\paginator.py", line 65, in page
    number = self.validate_number(number)
  File "C:\Users\Armstromg\Anaconda3\lib\site-packages\django\core\paginator.py", line 43, in validate_number
    if number > self.num_pages:
  File "C:\Users\Armstromg\Anaconda3\lib\site-packages\django\utils\functional.py", line 36, in __get__
    res = instance.__dict__[self.name] = self.func(instance)
  File "C:\Users\Armstromg\Anaconda3\lib\site-packages\django\core\paginator.py", line 95, in num_pages
    if self.count == 0 and not self.allow_empty_first_page:
  File "C:\Users\Armstromg\Anaconda3\lib\site-packages\django\utils\functional.py", line 36, in __get__
    res = instance.__dict__[self.name] = self.func(instance)
  File "C:\Users\Armstromg\Anaconda3\lib\site-packages\django\core\paginator.py", line 90, in count
    return len(self.object_list)
TypeError: object of type 'itertools.chain' has no len()
2018-03-19 13:53:34,788 [Thread-6:81228] [django.request:118] [exception:handle_uncaught_exception] [ERROR]- Internal Server Error: /searchPage
Traceback (most recent call last):
  File "C:\Users\Armstromg\Anaconda3\lib\site-packages\django\core\paginator.py", line 85, in count
    return self.object_list.count()
AttributeError: 'itertools.chain' object has no attribute 'count'

During handling of the above exception, another exception occurred:

Traceback (most recent call last):
  File "C:\Users\Armstromg\Anaconda3\lib\site-packages\django\core\handlers\exception.py", line 35, in inner
    response = get_response(request)
  File "C:\Users\Armstromg\Anaconda3\lib\site-packages\django\core\handlers\base.py", line 128, in _get_response
    response = self.process_exception_by_middleware(e, request)
  File "C:\Users\Armstromg\Anaconda3\lib\site-packages\django\core\handlers\base.py", line 126, in _get_response
    response = wrapped_callback(request, *callback_args, **callback_kwargs)
  File "D:\lilanqing\Project_local\python\maizixueyuan\django-web\bitcs_project\bitcs\views.py", line 66, in searchPage
    query_results = paginator.page(page)
  File "C:\Users\Armstromg\Anaconda3\lib\site-packages\django\core\paginator.py", line 65, in page
    number = self.validate_number(number)
  File "C:\Users\Armstromg\Anaconda3\lib\site-packages\django\core\paginator.py", line 43, in validate_number
    if number > self.num_pages:
  File "C:\Users\Armstromg\Anaconda3\lib\site-packages\django\utils\functional.py", line 36, in __get__
    res = instance.__dict__[self.name] = self.func(instance)
  File "C:\Users\Armstromg\Anaconda3\lib\site-packages\django\core\paginator.py", line 95, in num_pages
    if self.count == 0 and not self.allow_empty_first_page:
  File "C:\Users\Armstromg\Anaconda3\lib\site-packages\django\utils\functional.py", line 36, in __get__
    res = instance.__dict__[self.name] = self.func(instance)
  File "C:\Users\Armstromg\Anaconda3\lib\site-packages\django\core\paginator.py", line 90, in count
    return len(self.object_list)
TypeError: object of type 'itertools.chain' has no len()
2018-03-19 14:02:53,725 [Thread-3:84244] [django.request:118] [exception:handle_uncaught_exception] [ERROR]- Internal Server Error: /searchPage
Traceback (most recent call last):
  File "C:\Users\Armstromg\Anaconda3\lib\site-packages\django\core\handlers\exception.py", line 35, in inner
    response = get_response(request)
  File "C:\Users\Armstromg\Anaconda3\lib\site-packages\django\core\handlers\base.py", line 128, in _get_response
    response = self.process_exception_by_middleware(e, request)
  File "C:\Users\Armstromg\Anaconda3\lib\site-packages\django\core\handlers\base.py", line 126, in _get_response
    response = wrapped_callback(request, *callback_args, **callback_kwargs)
  File "D:\lilanqing\Project_local\python\maizixueyuan\django-web\bitcs_project\bitcs\views.py", line 58, in searchPage
    query_results1 = Inforday.objects.filter(title__icontains=query_str)
UnboundLocalError: local variable 'query_str' referenced before assignment
2018-03-19 14:05:17,129 [Thread-1:84968] [django.request:118] [exception:handle_uncaught_exception] [ERROR]- Internal Server Error: /searchPage
Traceback (most recent call last):
  File "C:\Users\Armstromg\Anaconda3\lib\site-packages\django\core\handlers\exception.py", line 35, in inner
    response = get_response(request)
  File "C:\Users\Armstromg\Anaconda3\lib\site-packages\django\core\handlers\base.py", line 128, in _get_response
    response = self.process_exception_by_middleware(e, request)
  File "C:\Users\Armstromg\Anaconda3\lib\site-packages\django\core\handlers\base.py", line 126, in _get_response
    response = wrapped_callback(request, *callback_args, **callback_kwargs)
  File "D:\lilanqing\Project_local\python\maizixueyuan\django-web\bitcs_project\bitcs\views.py", line 67, in searchPage
    query_results.extend(query_results3)
  File "C:\Users\Armstromg\Anaconda3\lib\site-packages\mongoengine\queryset\queryset.py", line 51, in __len__
    list(self._iter_results())
  File "C:\Users\Armstromg\Anaconda3\lib\site-packages\mongoengine\queryset\queryset.py", line 99, in _iter_results
    self._populate_cache()
  File "C:\Users\Armstromg\Anaconda3\lib\site-packages\mongoengine\queryset\queryset.py", line 118, in _populate_cache
    self._result_cache.append(next(self))
  File "C:\Users\Armstromg\Anaconda3\lib\site-packages\mongoengine\queryset\base.py", line 1473, in __next__
    only_fields=self.only_fields)
  File "C:\Users\Armstromg\Anaconda3\lib\site-packages\mongoengine\base\document.py", line 721, in _from_son
    obj = cls(__auto_convert=False, _created=created, __only_fields=only_fields, **data)
  File "C:\Users\Armstromg\Anaconda3\lib\site-packages\mongoengine\base\document.py", line 77, in __init__
    raise FieldDoesNotExist(msg)
mongoengine.errors.FieldDoesNotExist: The fields "{'Name'}" do not exist on the document "Inforconduction"
2018-03-19 14:05:17,425 [Thread-3:84016] [django.request:118] [exception:handle_uncaught_exception] [ERROR]- Internal Server Error: /searchPage
Traceback (most recent call last):
  File "C:\Users\Armstromg\Anaconda3\lib\site-packages\django\core\handlers\exception.py", line 35, in inner
    response = get_response(request)
  File "C:\Users\Armstromg\Anaconda3\lib\site-packages\django\core\handlers\base.py", line 128, in _get_response
    response = self.process_exception_by_middleware(e, request)
  File "C:\Users\Armstromg\Anaconda3\lib\site-packages\django\core\handlers\base.py", line 126, in _get_response
    response = wrapped_callback(request, *callback_args, **callback_kwargs)
  File "D:\lilanqing\Project_local\python\maizixueyuan\django-web\bitcs_project\bitcs\views.py", line 67, in searchPage
    query_results.extend(query_results3)
  File "C:\Users\Armstromg\Anaconda3\lib\site-packages\mongoengine\queryset\queryset.py", line 51, in __len__
    list(self._iter_results())
  File "C:\Users\Armstromg\Anaconda3\lib\site-packages\mongoengine\queryset\queryset.py", line 99, in _iter_results
    self._populate_cache()
  File "C:\Users\Armstromg\Anaconda3\lib\site-packages\mongoengine\queryset\queryset.py", line 118, in _populate_cache
    self._result_cache.append(next(self))
  File "C:\Users\Armstromg\Anaconda3\lib\site-packages\mongoengine\queryset\base.py", line 1473, in __next__
    only_fields=self.only_fields)
  File "C:\Users\Armstromg\Anaconda3\lib\site-packages\mongoengine\base\document.py", line 721, in _from_son
    obj = cls(__auto_convert=False, _created=created, __only_fields=only_fields, **data)
  File "C:\Users\Armstromg\Anaconda3\lib\site-packages\mongoengine\base\document.py", line 77, in __init__
    raise FieldDoesNotExist(msg)
mongoengine.errors.FieldDoesNotExist: The fields "{'Name'}" do not exist on the document "Inforconduction"
2018-03-19 14:05:30,896 [Thread-8:84248] [django.request:118] [exception:handle_uncaught_exception] [ERROR]- Internal Server Error: /searchPage
Traceback (most recent call last):
  File "C:\Users\Armstromg\Anaconda3\lib\site-packages\django\core\handlers\exception.py", line 35, in inner
    response = get_response(request)
  File "C:\Users\Armstromg\Anaconda3\lib\site-packages\django\core\handlers\base.py", line 128, in _get_response
    response = self.process_exception_by_middleware(e, request)
  File "C:\Users\Armstromg\Anaconda3\lib\site-packages\django\core\handlers\base.py", line 126, in _get_response
    response = wrapped_callback(request, *callback_args, **callback_kwargs)
  File "D:\lilanqing\Project_local\python\maizixueyuan\django-web\bitcs_project\bitcs\views.py", line 67, in searchPage
    query_results.extend(query_results3)
  File "C:\Users\Armstromg\Anaconda3\lib\site-packages\mongoengine\queryset\queryset.py", line 51, in __len__
    list(self._iter_results())
  File "C:\Users\Armstromg\Anaconda3\lib\site-packages\mongoengine\queryset\queryset.py", line 99, in _iter_results
    self._populate_cache()
  File "C:\Users\Armstromg\Anaconda3\lib\site-packages\mongoengine\queryset\queryset.py", line 118, in _populate_cache
    self._result_cache.append(next(self))
  File "C:\Users\Armstromg\Anaconda3\lib\site-packages\mongoengine\queryset\base.py", line 1473, in __next__
    only_fields=self.only_fields)
  File "C:\Users\Armstromg\Anaconda3\lib\site-packages\mongoengine\base\document.py", line 721, in _from_son
    obj = cls(__auto_convert=False, _created=created, __only_fields=only_fields, **data)
  File "C:\Users\Armstromg\Anaconda3\lib\site-packages\mongoengine\base\document.py", line 77, in __init__
    raise FieldDoesNotExist(msg)
mongoengine.errors.FieldDoesNotExist: The fields "{'Name'}" do not exist on the document "Inforconduction"
2018-03-19 14:35:00,030 [Thread-9:91888] [django.request:118] [exception:handle_uncaught_exception] [ERROR]- Internal Server Error: /searchPage
Traceback (most recent call last):
  File "C:\Users\Armstromg\Anaconda3\lib\site-packages\django\core\handlers\exception.py", line 35, in inner
    response = get_response(request)
  File "C:\Users\Armstromg\Anaconda3\lib\site-packages\django\core\handlers\base.py", line 128, in _get_response
    response = self.process_exception_by_middleware(e, request)
  File "C:\Users\Armstromg\Anaconda3\lib\site-packages\django\core\handlers\base.py", line 126, in _get_response
    response = wrapped_callback(request, *callback_args, **callback_kwargs)
  File "D:\lilanqing\Project_local\python\maizixueyuan\django-web\bitcs_project\bitcs\views.py", line 67, in searchPage
    query_results.extend(query_results3)
  File "C:\Users\Armstromg\Anaconda3\lib\site-packages\mongoengine\queryset\queryset.py", line 51, in __len__
    list(self._iter_results())
  File "C:\Users\Armstromg\Anaconda3\lib\site-packages\mongoengine\queryset\queryset.py", line 99, in _iter_results
    self._populate_cache()
  File "C:\Users\Armstromg\Anaconda3\lib\site-packages\mongoengine\queryset\queryset.py", line 118, in _populate_cache
    self._result_cache.append(next(self))
  File "C:\Users\Armstromg\Anaconda3\lib\site-packages\mongoengine\queryset\base.py", line 1473, in __next__
    only_fields=self.only_fields)
  File "C:\Users\Armstromg\Anaconda3\lib\site-packages\mongoengine\base\document.py", line 721, in _from_son
    obj = cls(__auto_convert=False, _created=created, __only_fields=only_fields, **data)
  File "C:\Users\Armstromg\Anaconda3\lib\site-packages\mongoengine\base\document.py", line 77, in __init__
    raise FieldDoesNotExist(msg)
mongoengine.errors.FieldDoesNotExist: The fields "{'Name'}" do not exist on the document "Inforconduction"
2018-03-19 14:39:49,211 [Thread-5:70164] [django.request:118] [exception:handle_uncaught_exception] [ERROR]- Internal Server Error: /searchPage
Traceback (most recent call last):
  File "C:\Users\Armstromg\Anaconda3\lib\site-packages\django\core\handlers\exception.py", line 35, in inner
    response = get_response(request)
  File "C:\Users\Armstromg\Anaconda3\lib\site-packages\django\core\handlers\base.py", line 128, in _get_response
    response = self.process_exception_by_middleware(e, request)
  File "C:\Users\Armstromg\Anaconda3\lib\site-packages\django\core\handlers\base.py", line 126, in _get_response
    response = wrapped_callback(request, *callback_args, **callback_kwargs)
  File "D:\lilanqing\Project_local\python\maizixueyuan\django-web\bitcs_project\bitcs\views.py", line 64, in searchPage
    query_results.extend(query_results3)
  File "C:\Users\Armstromg\Anaconda3\lib\site-packages\mongoengine\queryset\queryset.py", line 51, in __len__
    list(self._iter_results())
  File "C:\Users\Armstromg\Anaconda3\lib\site-packages\mongoengine\queryset\queryset.py", line 99, in _iter_results
    self._populate_cache()
  File "C:\Users\Armstromg\Anaconda3\lib\site-packages\mongoengine\queryset\queryset.py", line 118, in _populate_cache
    self._result_cache.append(next(self))
  File "C:\Users\Armstromg\Anaconda3\lib\site-packages\mongoengine\queryset\base.py", line 1473, in __next__
    only_fields=self.only_fields)
  File "C:\Users\Armstromg\Anaconda3\lib\site-packages\mongoengine\base\document.py", line 721, in _from_son
    obj = cls(__auto_convert=False, _created=created, __only_fields=only_fields, **data)
  File "C:\Users\Armstromg\Anaconda3\lib\site-packages\mongoengine\base\document.py", line 77, in __init__
    raise FieldDoesNotExist(msg)
mongoengine.errors.FieldDoesNotExist: The fields "{'Name'}" do not exist on the document "Inforconduction"
2018-03-19 14:40:54,174 [Thread-8:93356] [django.request:93] [base:get_response] [WARNING]- Not Found: /favicon.ico
2018-03-19 14:41:25,503 [Thread-11:93604] [django.request:118] [exception:handle_uncaught_exception] [ERROR]- Internal Server Error: /searchPage
Traceback (most recent call last):
  File "C:\Users\Armstromg\Anaconda3\lib\site-packages\django\core\handlers\exception.py", line 35, in inner
    response = get_response(request)
  File "C:\Users\Armstromg\Anaconda3\lib\site-packages\django\core\handlers\base.py", line 128, in _get_response
    response = self.process_exception_by_middleware(e, request)
  File "C:\Users\Armstromg\Anaconda3\lib\site-packages\django\core\handlers\base.py", line 126, in _get_response
    response = wrapped_callback(request, *callback_args, **callback_kwargs)
  File "D:\lilanqing\Project_local\python\maizixueyuan\django-web\bitcs_project\bitcs\views.py", line 64, in searchPage
    query_results.extend(query_results3)
  File "C:\Users\Armstromg\Anaconda3\lib\site-packages\mongoengine\queryset\queryset.py", line 51, in __len__
    list(self._iter_results())
  File "C:\Users\Armstromg\Anaconda3\lib\site-packages\mongoengine\queryset\queryset.py", line 99, in _iter_results
    self._populate_cache()
  File "C:\Users\Armstromg\Anaconda3\lib\site-packages\mongoengine\queryset\queryset.py", line 118, in _populate_cache
    self._result_cache.append(next(self))
  File "C:\Users\Armstromg\Anaconda3\lib\site-packages\mongoengine\queryset\base.py", line 1473, in __next__
    only_fields=self.only_fields)
  File "C:\Users\Armstromg\Anaconda3\lib\site-packages\mongoengine\base\document.py", line 721, in _from_son
    obj = cls(__auto_convert=False, _created=created, __only_fields=only_fields, **data)
  File "C:\Users\Armstromg\Anaconda3\lib\site-packages\mongoengine\base\document.py", line 77, in __init__
    raise FieldDoesNotExist(msg)
mongoengine.errors.FieldDoesNotExist: The fields "{'Name'}" do not exist on the document "Inforconduction"
2018-03-19 14:41:48,349 [Thread-12:92404] [django.request:118] [exception:handle_uncaught_exception] [ERROR]- Internal Server Error: /searchPage
Traceback (most recent call last):
  File "C:\Users\Armstromg\Anaconda3\lib\site-packages\django\core\handlers\exception.py", line 35, in inner
    response = get_response(request)
  File "C:\Users\Armstromg\Anaconda3\lib\site-packages\django\core\handlers\base.py", line 128, in _get_response
    response = self.process_exception_by_middleware(e, request)
  File "C:\Users\Armstromg\Anaconda3\lib\site-packages\django\core\handlers\base.py", line 126, in _get_response
    response = wrapped_callback(request, *callback_args, **callback_kwargs)
  File "D:\lilanqing\Project_local\python\maizixueyuan\django-web\bitcs_project\bitcs\views.py", line 64, in searchPage
    query_results.extend(query_results3)
  File "C:\Users\Armstromg\Anaconda3\lib\site-packages\mongoengine\queryset\queryset.py", line 51, in __len__
    list(self._iter_results())
  File "C:\Users\Armstromg\Anaconda3\lib\site-packages\mongoengine\queryset\queryset.py", line 99, in _iter_results
    self._populate_cache()
  File "C:\Users\Armstromg\Anaconda3\lib\site-packages\mongoengine\queryset\queryset.py", line 118, in _populate_cache
    self._result_cache.append(next(self))
  File "C:\Users\Armstromg\Anaconda3\lib\site-packages\mongoengine\queryset\base.py", line 1473, in __next__
    only_fields=self.only_fields)
  File "C:\Users\Armstromg\Anaconda3\lib\site-packages\mongoengine\base\document.py", line 721, in _from_son
    obj = cls(__auto_convert=False, _created=created, __only_fields=only_fields, **data)
  File "C:\Users\Armstromg\Anaconda3\lib\site-packages\mongoengine\base\document.py", line 77, in __init__
    raise FieldDoesNotExist(msg)
mongoengine.errors.FieldDoesNotExist: The fields "{'Name'}" do not exist on the document "Inforconduction"
2018-03-19 14:44:07,963 [Thread-18:94088] [django.request:118] [exception:handle_uncaught_exception] [ERROR]- Internal Server Error: /searchPage
Traceback (most recent call last):
  File "C:\Users\Armstromg\Anaconda3\lib\site-packages\django\core\handlers\exception.py", line 35, in inner
    response = get_response(request)
  File "C:\Users\Armstromg\Anaconda3\lib\site-packages\django\core\handlers\base.py", line 128, in _get_response
    response = self.process_exception_by_middleware(e, request)
  File "C:\Users\Armstromg\Anaconda3\lib\site-packages\django\core\handlers\base.py", line 126, in _get_response
    response = wrapped_callback(request, *callback_args, **callback_kwargs)
  File "D:\lilanqing\Project_local\python\maizixueyuan\django-web\bitcs_project\bitcs\views.py", line 64, in searchPage
    query_results.extend(query_results3)
  File "C:\Users\Armstromg\Anaconda3\lib\site-packages\mongoengine\queryset\queryset.py", line 51, in __len__
    list(self._iter_results())
  File "C:\Users\Armstromg\Anaconda3\lib\site-packages\mongoengine\queryset\queryset.py", line 99, in _iter_results
    self._populate_cache()
  File "C:\Users\Armstromg\Anaconda3\lib\site-packages\mongoengine\queryset\queryset.py", line 118, in _populate_cache
    self._result_cache.append(next(self))
  File "C:\Users\Armstromg\Anaconda3\lib\site-packages\mongoengine\queryset\base.py", line 1473, in __next__
    only_fields=self.only_fields)
  File "C:\Users\Armstromg\Anaconda3\lib\site-packages\mongoengine\base\document.py", line 721, in _from_son
    obj = cls(__auto_convert=False, _created=created, __only_fields=only_fields, **data)
  File "C:\Users\Armstromg\Anaconda3\lib\site-packages\mongoengine\base\document.py", line 77, in __init__
    raise FieldDoesNotExist(msg)
mongoengine.errors.FieldDoesNotExist: The fields "{'Name'}" do not exist on the document "Inforconduction"
2018-03-19 14:44:37,139 [Thread-23:94712] [django.request:118] [exception:handle_uncaught_exception] [ERROR]- Internal Server Error: /searchPage
Traceback (most recent call last):
  File "C:\Users\Armstromg\Anaconda3\lib\site-packages\django\core\handlers\exception.py", line 35, in inner
    response = get_response(request)
  File "C:\Users\Armstromg\Anaconda3\lib\site-packages\django\core\handlers\base.py", line 128, in _get_response
    response = self.process_exception_by_middleware(e, request)
  File "C:\Users\Armstromg\Anaconda3\lib\site-packages\django\core\handlers\base.py", line 126, in _get_response
    response = wrapped_callback(request, *callback_args, **callback_kwargs)
  File "D:\lilanqing\Project_local\python\maizixueyuan\django-web\bitcs_project\bitcs\views.py", line 64, in searchPage
    query_results.extend(query_results3)
  File "C:\Users\Armstromg\Anaconda3\lib\site-packages\mongoengine\queryset\queryset.py", line 51, in __len__
    list(self._iter_results())
  File "C:\Users\Armstromg\Anaconda3\lib\site-packages\mongoengine\queryset\queryset.py", line 99, in _iter_results
    self._populate_cache()
  File "C:\Users\Armstromg\Anaconda3\lib\site-packages\mongoengine\queryset\queryset.py", line 118, in _populate_cache
    self._result_cache.append(next(self))
  File "C:\Users\Armstromg\Anaconda3\lib\site-packages\mongoengine\queryset\base.py", line 1473, in __next__
    only_fields=self.only_fields)
  File "C:\Users\Armstromg\Anaconda3\lib\site-packages\mongoengine\base\document.py", line 721, in _from_son
    obj = cls(__auto_convert=False, _created=created, __only_fields=only_fields, **data)
  File "C:\Users\Armstromg\Anaconda3\lib\site-packages\mongoengine\base\document.py", line 77, in __init__
    raise FieldDoesNotExist(msg)
mongoengine.errors.FieldDoesNotExist: The fields "{'Name'}" do not exist on the document "Inforconduction"
2018-03-19 14:54:50,142 [Thread-40:96908] [django.request:118] [exception:handle_uncaught_exception] [ERROR]- Internal Server Error: /searchPage
Traceback (most recent call last):
  File "C:\Users\Armstromg\Anaconda3\lib\site-packages\django\template\base.py", line 475, in parse
    compile_func = self.tags[command]
KeyError: 'next_ten_page'

During handling of the above exception, another exception occurred:

Traceback (most recent call last):
  File "C:\Users\Armstromg\Anaconda3\lib\site-packages\django\core\handlers\exception.py", line 35, in inner
    response = get_response(request)
  File "C:\Users\Armstromg\Anaconda3\lib\site-packages\django\core\handlers\base.py", line 128, in _get_response
    response = self.process_exception_by_middleware(e, request)
  File "C:\Users\Armstromg\Anaconda3\lib\site-packages\django\core\handlers\base.py", line 126, in _get_response
    response = wrapped_callback(request, *callback_args, **callback_kwargs)
  File "D:\lilanqing\Project_local\python\maizixueyuan\django-web\bitcs_project\bitcs\views.py", line 73, in searchPage
    return render(request, 'searchPage.html', locals())
  File "C:\Users\Armstromg\Anaconda3\lib\site-packages\django\shortcuts.py", line 36, in render
    content = loader.render_to_string(template_name, context, request, using=using)
  File "C:\Users\Armstromg\Anaconda3\lib\site-packages\django\template\loader.py", line 61, in render_to_string
    template = get_template(template_name, using=using)
  File "C:\Users\Armstromg\Anaconda3\lib\site-packages\django\template\loader.py", line 15, in get_template
    return engine.get_template(template_name)
  File "C:\Users\Armstromg\Anaconda3\lib\site-packages\django\template\backends\django.py", line 34, in get_template
    return Template(self.engine.get_template(template_name), self)
  File "C:\Users\Armstromg\Anaconda3\lib\site-packages\django\template\engine.py", line 144, in get_template
    template, origin = self.find_template(template_name)
  File "C:\Users\Armstromg\Anaconda3\lib\site-packages\django\template\engine.py", line 126, in find_template
    template = loader.get_template(name, skip=skip)
  File "C:\Users\Armstromg\Anaconda3\lib\site-packages\django\template\loaders\base.py", line 30, in get_template
    contents, origin, origin.template_name, self.engine,
  File "C:\Users\Armstromg\Anaconda3\lib\site-packages\django\template\base.py", line 160, in __init__
    self.nodelist = self.compile_nodelist()
  File "C:\Users\Armstromg\Anaconda3\lib\site-packages\django\template\base.py", line 198, in compile_nodelist
    return parser.parse()
  File "C:\Users\Armstromg\Anaconda3\lib\site-packages\django\template\base.py", line 483, in parse
    raise self.error(token, e)
  File "C:\Users\Armstromg\Anaconda3\lib\site-packages\django\template\base.py", line 481, in parse
    compiled_result = compile_func(self, token)
  File "C:\Users\Armstromg\Anaconda3\lib\site-packages\django\template\loader_tags.py", line 290, in do_extends
    nodelist = parser.parse()
  File "C:\Users\Armstromg\Anaconda3\lib\site-packages\django\template\base.py", line 483, in parse
    raise self.error(token, e)
  File "C:\Users\Armstromg\Anaconda3\lib\site-packages\django\template\base.py", line 481, in parse
    compiled_result = compile_func(self, token)
  File "C:\Users\Armstromg\Anaconda3\lib\site-packages\django\template\loader_tags.py", line 233, in do_block
    nodelist = parser.parse(('endblock',))
  File "C:\Users\Armstromg\Anaconda3\lib\site-packages\django\template\base.py", line 483, in parse
    raise self.error(token, e)
  File "C:\Users\Armstromg\Anaconda3\lib\site-packages\django\template\base.py", line 481, in parse
    compiled_result = compile_func(self, token)
  File "C:\Users\Armstromg\Anaconda3\lib\site-packages\django\template\defaulttags.py", line 956, in do_if
    nodelist = parser.parse(('elif', 'else', 'endif'))
  File "C:\Users\Armstromg\Anaconda3\lib\site-packages\django\template\base.py", line 477, in parse
    self.invalid_block_tag(token, command, parse_until)
  File "C:\Users\Armstromg\Anaconda3\lib\site-packages\django\template\base.py", line 533, in invalid_block_tag
    get_text_list(["'%s'" % p for p in parse_until], 'or'),
django.template.exceptions.TemplateSyntaxError: Invalid block tag on line 54: 'next_ten_page', expected 'elif', 'else' or 'endif'. Did you forget to register or load this tag?
2018-03-19 14:55:06,198 [Thread-39:96700] [django.request:118] [exception:handle_uncaught_exception] [ERROR]- Internal Server Error: /searchPage
Traceback (most recent call last):
  File "C:\Users\Armstromg\Anaconda3\lib\site-packages\django\core\handlers\exception.py", line 35, in inner
    response = get_response(request)
  File "C:\Users\Armstromg\Anaconda3\lib\site-packages\django\core\handlers\base.py", line 128, in _get_response
    response = self.process_exception_by_middleware(e, request)
  File "C:\Users\Armstromg\Anaconda3\lib\site-packages\django\core\handlers\base.py", line 126, in _get_response
    response = wrapped_callback(request, *callback_args, **callback_kwargs)
  File "D:\lilanqing\Project_local\python\maizixueyuan\django-web\bitcs_project\bitcs\views.py", line 64, in searchPage
    query_results.extend(query_results3)
  File "C:\Users\Armstromg\Anaconda3\lib\site-packages\mongoengine\queryset\queryset.py", line 51, in __len__
    list(self._iter_results())
  File "C:\Users\Armstromg\Anaconda3\lib\site-packages\mongoengine\queryset\queryset.py", line 99, in _iter_results
    self._populate_cache()
  File "C:\Users\Armstromg\Anaconda3\lib\site-packages\mongoengine\queryset\queryset.py", line 118, in _populate_cache
    self._result_cache.append(next(self))
  File "C:\Users\Armstromg\Anaconda3\lib\site-packages\mongoengine\queryset\base.py", line 1473, in __next__
    only_fields=self.only_fields)
  File "C:\Users\Armstromg\Anaconda3\lib\site-packages\mongoengine\base\document.py", line 721, in _from_son
    obj = cls(__auto_convert=False, _created=created, __only_fields=only_fields, **data)
  File "C:\Users\Armstromg\Anaconda3\lib\site-packages\mongoengine\base\document.py", line 77, in __init__
    raise FieldDoesNotExist(msg)
mongoengine.errors.FieldDoesNotExist: The fields "{'Name'}" do not exist on the document "Inforconduction"
2018-03-19 15:38:14,291 [Thread-48:106876] [django.request:118] [exception:handle_uncaught_exception] [ERROR]- Internal Server Error: /searchPage
Traceback (most recent call last):
  File "C:\Users\Armstromg\Anaconda3\lib\site-packages\django\core\handlers\exception.py", line 35, in inner
    response = get_response(request)
  File "C:\Users\Armstromg\Anaconda3\lib\site-packages\django\core\handlers\base.py", line 128, in _get_response
    response = self.process_exception_by_middleware(e, request)
  File "C:\Users\Armstromg\Anaconda3\lib\site-packages\django\core\handlers\base.py", line 126, in _get_response
    response = wrapped_callback(request, *callback_args, **callback_kwargs)
  File "D:\lilanqing\Project_local\python\maizixueyuan\django-web\bitcs_project\bitcs\views.py", line 64, in searchPage
    query_results.extend(query_results3)
  File "C:\Users\Armstromg\Anaconda3\lib\site-packages\mongoengine\queryset\queryset.py", line 51, in __len__
    list(self._iter_results())
  File "C:\Users\Armstromg\Anaconda3\lib\site-packages\mongoengine\queryset\queryset.py", line 99, in _iter_results
    self._populate_cache()
  File "C:\Users\Armstromg\Anaconda3\lib\site-packages\mongoengine\queryset\queryset.py", line 118, in _populate_cache
    self._result_cache.append(next(self))
  File "C:\Users\Armstromg\Anaconda3\lib\site-packages\mongoengine\queryset\base.py", line 1473, in __next__
    only_fields=self.only_fields)
  File "C:\Users\Armstromg\Anaconda3\lib\site-packages\mongoengine\base\document.py", line 721, in _from_son
    obj = cls(__auto_convert=False, _created=created, __only_fields=only_fields, **data)
  File "C:\Users\Armstromg\Anaconda3\lib\site-packages\mongoengine\base\document.py", line 77, in __init__
    raise FieldDoesNotExist(msg)
mongoengine.errors.FieldDoesNotExist: The fields "{'Name'}" do not exist on the document "Inforconduction"
2018-03-19 15:38:25,728 [Thread-50:106784] [django.request:118] [exception:handle_uncaught_exception] [ERROR]- Internal Server Error: /searchPage
Traceback (most recent call last):
  File "C:\Users\Armstromg\Anaconda3\lib\site-packages\django\core\handlers\exception.py", line 35, in inner
    response = get_response(request)
  File "C:\Users\Armstromg\Anaconda3\lib\site-packages\django\core\handlers\base.py", line 128, in _get_response
    response = self.process_exception_by_middleware(e, request)
  File "C:\Users\Armstromg\Anaconda3\lib\site-packages\django\core\handlers\base.py", line 126, in _get_response
    response = wrapped_callback(request, *callback_args, **callback_kwargs)
  File "D:\lilanqing\Project_local\python\maizixueyuan\django-web\bitcs_project\bitcs\views.py", line 64, in searchPage
    query_results.extend(query_results3)
  File "C:\Users\Armstromg\Anaconda3\lib\site-packages\mongoengine\queryset\queryset.py", line 51, in __len__
    list(self._iter_results())
  File "C:\Users\Armstromg\Anaconda3\lib\site-packages\mongoengine\queryset\queryset.py", line 99, in _iter_results
    self._populate_cache()
  File "C:\Users\Armstromg\Anaconda3\lib\site-packages\mongoengine\queryset\queryset.py", line 118, in _populate_cache
    self._result_cache.append(next(self))
  File "C:\Users\Armstromg\Anaconda3\lib\site-packages\mongoengine\queryset\base.py", line 1473, in __next__
    only_fields=self.only_fields)
  File "C:\Users\Armstromg\Anaconda3\lib\site-packages\mongoengine\base\document.py", line 721, in _from_son
    obj = cls(__auto_convert=False, _created=created, __only_fields=only_fields, **data)
  File "C:\Users\Armstromg\Anaconda3\lib\site-packages\mongoengine\base\document.py", line 77, in __init__
    raise FieldDoesNotExist(msg)
mongoengine.errors.FieldDoesNotExist: The fields "{'Name'}" do not exist on the document "Inforconduction"
2018-03-19 15:39:21,069 [Thread-52:107956] [django.request:118] [exception:handle_uncaught_exception] [ERROR]- Internal Server Error: /searchPage
Traceback (most recent call last):
  File "C:\Users\Armstromg\Anaconda3\lib\site-packages\django\core\handlers\exception.py", line 35, in inner
    response = get_response(request)
  File "C:\Users\Armstromg\Anaconda3\lib\site-packages\django\core\handlers\base.py", line 128, in _get_response
    response = self.process_exception_by_middleware(e, request)
  File "C:\Users\Armstromg\Anaconda3\lib\site-packages\django\core\handlers\base.py", line 126, in _get_response
    response = wrapped_callback(request, *callback_args, **callback_kwargs)
  File "D:\lilanqing\Project_local\python\maizixueyuan\django-web\bitcs_project\bitcs\views.py", line 64, in searchPage
    query_results.extend(query_results3)
  File "C:\Users\Armstromg\Anaconda3\lib\site-packages\mongoengine\queryset\queryset.py", line 51, in __len__
    list(self._iter_results())
  File "C:\Users\Armstromg\Anaconda3\lib\site-packages\mongoengine\queryset\queryset.py", line 99, in _iter_results
    self._populate_cache()
  File "C:\Users\Armstromg\Anaconda3\lib\site-packages\mongoengine\queryset\queryset.py", line 118, in _populate_cache
    self._result_cache.append(next(self))
  File "C:\Users\Armstromg\Anaconda3\lib\site-packages\mongoengine\queryset\base.py", line 1473, in __next__
    only_fields=self.only_fields)
  File "C:\Users\Armstromg\Anaconda3\lib\site-packages\mongoengine\base\document.py", line 721, in _from_son
    obj = cls(__auto_convert=False, _created=created, __only_fields=only_fields, **data)
  File "C:\Users\Armstromg\Anaconda3\lib\site-packages\mongoengine\base\document.py", line 77, in __init__
    raise FieldDoesNotExist(msg)
mongoengine.errors.FieldDoesNotExist: The fields "{'Name'}" do not exist on the document "Inforconduction"
2018-03-19 15:58:37,384 [Thread-1:111928] [django.request:118] [exception:handle_uncaught_exception] [ERROR]- Internal Server Error: /searchPage
Traceback (most recent call last):
  File "C:\Users\Armstromg\Anaconda3\lib\site-packages\django\utils\datastructures.py", line 77, in __getitem__
    list_ = super().__getitem__(key)
KeyError: 'kw'

During handling of the above exception, another exception occurred:

Traceback (most recent call last):
  File "C:\Users\Armstromg\Anaconda3\lib\site-packages\django\core\handlers\exception.py", line 35, in inner
    response = get_response(request)
  File "C:\Users\Armstromg\Anaconda3\lib\site-packages\django\core\handlers\base.py", line 128, in _get_response
    response = self.process_exception_by_middleware(e, request)
  File "C:\Users\Armstromg\Anaconda3\lib\site-packages\django\core\handlers\base.py", line 126, in _get_response
    response = wrapped_callback(request, *callback_args, **callback_kwargs)
  File "D:\lilanqing\Project_local\python\maizixueyuan\django-web\bitcs_project\bitcs\views.py", line 57, in searchPage
    kw = request.POST['kw']
  File "C:\Users\Armstromg\Anaconda3\lib\site-packages\django\utils\datastructures.py", line 79, in __getitem__
    raise MultiValueDictKeyError(key)
django.utils.datastructures.MultiValueDictKeyError: 'kw'
2018-03-19 15:59:17,092 [Thread-4:112500] [django.request:93] [base:get_response] [WARNING]- Not Found: /favicon.ico
2018-03-19 15:59:20,665 [Thread-6:112644] [django.request:118] [exception:handle_uncaught_exception] [ERROR]- Internal Server Error: /searchPage
Traceback (most recent call last):
  File "C:\Users\Armstromg\Anaconda3\lib\site-packages\django\utils\datastructures.py", line 77, in __getitem__
    list_ = super().__getitem__(key)
KeyError: 'kw'

During handling of the above exception, another exception occurred:

Traceback (most recent call last):
  File "C:\Users\Armstromg\Anaconda3\lib\site-packages\django\core\handlers\exception.py", line 35, in inner
    response = get_response(request)
  File "C:\Users\Armstromg\Anaconda3\lib\site-packages\django\core\handlers\base.py", line 128, in _get_response
    response = self.process_exception_by_middleware(e, request)
  File "C:\Users\Armstromg\Anaconda3\lib\site-packages\django\core\handlers\base.py", line 126, in _get_response
    response = wrapped_callback(request, *callback_args, **callback_kwargs)
  File "D:\lilanqing\Project_local\python\maizixueyuan\django-web\bitcs_project\bitcs\views.py", line 57, in searchPage
    kw = request.POST['kw']
  File "C:\Users\Armstromg\Anaconda3\lib\site-packages\django\utils\datastructures.py", line 79, in __getitem__
    raise MultiValueDictKeyError(key)
django.utils.datastructures.MultiValueDictKeyError: 'kw'
2018-03-19 16:53:06,161 [Thread-13:125060] [django.request:93] [base:get_response] [WARNING]- Not Found: /favicon.ico
2018-03-21 10:07:09,263 [Thread-3:24232] [django.request:93] [base:get_response] [WARNING]- Not Found: /favicon.ico
2018-03-22 11:26:21,171 [Thread-5:53896] [django.request:93] [base:get_response] [WARNING]- Not Found: /favicon.ico
2018-06-11 11:00:07,678 [Thread-1:9332] [django.request:93] [base:get_response] [WARNING]- Not Found: /favicon.ico
2018-06-11 11:00:13,489 [Thread-6:9608] [django.request:93] [base:get_response] [WARNING]- Not Found: /favicon.ico
