2018-03-12 15:15:22,190 [Thread-8:4272] [django.request:93] [base:get_response] [WARNING]- Not Found: /news.html
2018-03-12 15:33:12,426 [Thread-2:7856] [django.request:118] [exception:handle_uncaught_exception] [ERROR]- Internal Server Error: /
Traceback (most recent call last):
  File "C:\Users\Armstromg\Anaconda3\lib\site-packages\django\core\handlers\exception.py", line 35, in inner
    response = get_response(request)
  File "C:\Users\Armstromg\Anaconda3\lib\site-packages\django\core\handlers\base.py", line 128, in _get_response
    response = self.process_exception_by_middleware(e, request)
  File "C:\Users\Armstromg\Anaconda3\lib\site-packages\django\core\handlers\base.py", line 126, in _get_response
    response = wrapped_callback(request, *callback_args, **callback_kwargs)
  File "D:\lilanqing\Project_local\python\maizixueyuan\django-web\blog_project2\blog\views.py", line 18, in index
    return render(requset, 'index.html', locals())
  File "C:\Users\Armstromg\Anaconda3\lib\site-packages\django\shortcuts.py", line 36, in render
    content = loader.render_to_string(template_name, context, request, using=using)
  File "C:\Users\Armstromg\Anaconda3\lib\site-packages\django\template\loader.py", line 62, in render_to_string
    return template.render(context, request)
  File "C:\Users\Armstromg\Anaconda3\lib\site-packages\django\template\backends\django.py", line 61, in render
    return self.template.render(context)
  File "C:\Users\Armstromg\Anaconda3\lib\site-packages\django\template\base.py", line 173, in render
    with context.bind_template(self):
  File "C:\Users\Armstromg\Anaconda3\lib\contextlib.py", line 81, in __enter__
    return next(self.gen)
  File "C:\Users\Armstromg\Anaconda3\lib\site-packages\django\template\context.py", line 250, in bind_template
    updates.update(processor(self.request))
TypeError: global_setting() takes 0 positional arguments but 1 was given
2018-03-12 15:33:23,256 [Thread-8:7792] [django.request:118] [exception:handle_uncaught_exception] [ERROR]- Internal Server Error: /
Traceback (most recent call last):
  File "C:\Users\Armstromg\Anaconda3\lib\site-packages\django\core\handlers\exception.py", line 35, in inner
    response = get_response(request)
  File "C:\Users\Armstromg\Anaconda3\lib\site-packages\django\core\handlers\base.py", line 128, in _get_response
    response = self.process_exception_by_middleware(e, request)
  File "C:\Users\Armstromg\Anaconda3\lib\site-packages\django\core\handlers\base.py", line 126, in _get_response
    response = wrapped_callback(request, *callback_args, **callback_kwargs)
  File "D:\lilanqing\Project_local\python\maizixueyuan\django-web\blog_project2\blog\views.py", line 18, in index
    return render(requset, 'index.html', locals())
  File "C:\Users\Armstromg\Anaconda3\lib\site-packages\django\shortcuts.py", line 36, in render
    content = loader.render_to_string(template_name, context, request, using=using)
  File "C:\Users\Armstromg\Anaconda3\lib\site-packages\django\template\loader.py", line 62, in render_to_string
    return template.render(context, request)
  File "C:\Users\Armstromg\Anaconda3\lib\site-packages\django\template\backends\django.py", line 61, in render
    return self.template.render(context)
  File "C:\Users\Armstromg\Anaconda3\lib\site-packages\django\template\base.py", line 173, in render
    with context.bind_template(self):
  File "C:\Users\Armstromg\Anaconda3\lib\contextlib.py", line 81, in __enter__
    return next(self.gen)
  File "C:\Users\Armstromg\Anaconda3\lib\site-packages\django\template\context.py", line 250, in bind_template
    updates.update(processor(self.request))
TypeError: global_setting() takes 0 positional arguments but 1 was given
2018-03-12 16:32:52,398 [Thread-8:5724] [django.request:93] [base:get_response] [WARNING]- Not Found: /favicon.ico
2018-03-12 17:17:46,801 [Thread-43:2444] [django.request:93] [base:get_response] [WARNING]- Not Found: /favicon.ico
2018-03-13 10:19:56,083 [Thread-3:2820] [django.request:93] [base:get_response] [WARNING]- Not Found: /favicon.ico
2018-03-13 10:20:59,156 [Thread-8:8140] [django.request:93] [base:get_response] [WARNING]- Not Found: /favicon.ico
2018-03-13 10:50:36,482 [Thread-19:2100] [django.request:118] [exception:handle_uncaught_exception] [ERROR]- Internal Server Error: /
Traceback (most recent call last):
  File "C:\Users\Armstromg\Anaconda3\lib\site-packages\django\template\base.py", line 475, in parse
    compile_func = self.tags[command]
KeyError: 'endfor'

During handling of the above exception, another exception occurred:

Traceback (most recent call last):
  File "C:\Users\Armstromg\Anaconda3\lib\site-packages\django\core\handlers\exception.py", line 35, in inner
    response = get_response(request)
  File "C:\Users\Armstromg\Anaconda3\lib\site-packages\django\core\handlers\base.py", line 128, in _get_response
    response = self.process_exception_by_middleware(e, request)
  File "C:\Users\Armstromg\Anaconda3\lib\site-packages\django\core\handlers\base.py", line 126, in _get_response
    response = wrapped_callback(request, *callback_args, **callback_kwargs)
  File "D:\lilanqing\Project_local\python\maizixueyuan\django-web\blog_project2\blog\views.py", line 26, in index
    return render(requset, 'index.html', locals())
  File "C:\Users\Armstromg\Anaconda3\lib\site-packages\django\shortcuts.py", line 36, in render
    content = loader.render_to_string(template_name, context, request, using=using)
  File "C:\Users\Armstromg\Anaconda3\lib\site-packages\django\template\loader.py", line 61, in render_to_string
    template = get_template(template_name, using=using)
  File "C:\Users\Armstromg\Anaconda3\lib\site-packages\django\template\loader.py", line 15, in get_template
    return engine.get_template(template_name)
  File "C:\Users\Armstromg\Anaconda3\lib\site-packages\django\template\backends\django.py", line 34, in get_template
    return Template(self.engine.get_template(template_name), self)
  File "C:\Users\Armstromg\Anaconda3\lib\site-packages\django\template\engine.py", line 144, in get_template
    template, origin = self.find_template(template_name)
  File "C:\Users\Armstromg\Anaconda3\lib\site-packages\django\template\engine.py", line 126, in find_template
    template = loader.get_template(name, skip=skip)
  File "C:\Users\Armstromg\Anaconda3\lib\site-packages\django\template\loaders\base.py", line 30, in get_template
    contents, origin, origin.template_name, self.engine,
  File "C:\Users\Armstromg\Anaconda3\lib\site-packages\django\template\base.py", line 160, in __init__
    self.nodelist = self.compile_nodelist()
  File "C:\Users\Armstromg\Anaconda3\lib\site-packages\django\template\base.py", line 198, in compile_nodelist
    return parser.parse()
  File "C:\Users\Armstromg\Anaconda3\lib\site-packages\django\template\base.py", line 483, in parse
    raise self.error(token, e)
  File "C:\Users\Armstromg\Anaconda3\lib\site-packages\django\template\base.py", line 481, in parse
    compiled_result = compile_func(self, token)
  File "C:\Users\Armstromg\Anaconda3\lib\site-packages\django\template\loader_tags.py", line 290, in do_extends
    nodelist = parser.parse()
  File "C:\Users\Armstromg\Anaconda3\lib\site-packages\django\template\base.py", line 483, in parse
    raise self.error(token, e)
  File "C:\Users\Armstromg\Anaconda3\lib\site-packages\django\template\base.py", line 481, in parse
    compiled_result = compile_func(self, token)
  File "C:\Users\Armstromg\Anaconda3\lib\site-packages\django\template\loader_tags.py", line 233, in do_block
    nodelist = parser.parse(('endblock',))
  File "C:\Users\Armstromg\Anaconda3\lib\site-packages\django\template\base.py", line 477, in parse
    self.invalid_block_tag(token, command, parse_until)
  File "C:\Users\Armstromg\Anaconda3\lib\site-packages\django\template\base.py", line 533, in invalid_block_tag
    get_text_list(["'%s'" % p for p in parse_until], 'or'),
django.template.exceptions.TemplateSyntaxError: Invalid block tag on line 15: 'endfor', expected 'endblock'. Did you forget to register or load this tag?
